Workbook

Sheet Read Me
A1: How to read this workbook
A3: Summary | B3: Key numbers with a verdict and a plain-language meaning, the balance curve, and the diagnosis.
A4: Monthly | B4: One row per month: trades, win rate, net profit, profit factor, start/end balance, return.
A5: Breakdown | B5: Results split by side, exit reason, hold time, weekday and entry hour.
A6: Trades | B6: Every trade on one row: the MT5 entry deal matched to its exit deal, plus a sentence explaining what happened. Use the filter arrows in the header row.
A7: Settings | B7: The EA inputs used in this test, with the important ones explained.
A9: R multiple | B9: Profit divided by the planned risk. +2R = won twice the risk, -1R = lost the planned risk.
A10: Planned risk $ | B10: Distance from order price to initial SL x lots x 100 oz.
A11: Entry slippage $ | B11: How much worse than the order price the trade filled. Positive = worse.
A12: Exit reason | B12: Initial stop loss = full loss. Breakeven/trailing stop = stop had been moved to the order price or beyond (can still be a small loss because of slippage). Closed by EA = closed without an SL comment (account guard, blackout, instant close).
A13: Win / Loss / Flat | B13: Flat = closed at exactly $0.00. MT5 counts those as profit trades, so its win count can be a little higher than here.
A14: Times | B14: All times are the broker SERVER time used by the tester.
A15: Colours | B15: Blue numbers = source data from the MT5 report. Black = formulas. Yellow = the settings that matter most.
A16: Source | B16: Built from the MT5 Strategy Tester report (1845 trades). All totals match the report's Total Net Profit.

Sheet Summary
B1: Backtest summary: plain-language version
B2: XAUUSD_Simple_Breakout_v7 | XAUUSD.T | H1 (2022.04.01 - 2026.10.01)
B3: Inputs (blue): change them and every number recalculates.
B5: Starting balance | C5: 5000 | E5: From the report (Initial Deposit).
B6: Contract size (oz per 1.00 lot) | C6: 100 | E6: Assumption: standard XAUUSD contract (1 lot = 100 oz). Used for planned risk $.
B8: Metric | C8: Value | D8: Verdict | E8: What it means
B9: RESULT
B10: Net profit | C10: =SUM(Trades!$W$2:$W$1846) -> -187.56 | D10: =IF(C10>0,"Profitable","Losing") -> Losing | E10: Total money made or lost over the whole test.
B11: Final balance | C11: =C5+C10 -> 4812.44 | E11: Starting balance + net profit.
B12: Return on starting balance | C12: =IFERROR(C10/C5,0) -> -0.037512 | E12: Net profit as % of the deposit.
B13: Max drawdown $ | C13: =MAX(Trades!$AB$2:$AB$1846) -> 2028.55 | E13: Biggest drop from a balance peak to a later low (closed trades).
B14: Max drawdown % | C14: =MAX(Trades!$AC$2:$AC$1846) -> 0.40571 | D14: =IF(C14<=0.08,"OK for prop","Too deep") -> Too deep | E14: Same drop as % of the peak. Prop firms usually fail you at 8-10%.
B15: TRADES
B16: Total trades | C16: =COUNT(Trades!$W$2:$W$1846) -> 1845 | E16: Each row of the Trades sheet = one entry + its exit.
B17: Winning trades | C17: =COUNTIF(Trades!$Y$2:$Y$1846,"Win") -> 1311
B18: Losing trades | C18: =COUNTIF(Trades!$Y$2:$Y$1846,"Loss") -> 534
B19: Win rate | C19: =IFERROR(C17/C16,0) -> 0.71056911 | D19: =IF(C19>=C23,"Above break-even","Below break-even") -> Below break-even | E19: Share of trades that made money.
B20: Average win | C20: =IFERROR(AVERAGEIF(Trades!$W$2:$W$1846,">0"),0) -> 14.661312 | E20: Typical size of a winner.
B21: Average loss | C21: =IFERROR(AVERAGEIF(Trades!$W$2:$W$1846,"<0"),0) -> -36.345581 | E21: Typical size of a loser.
B22: Win/loss size ratio | C22: =IFERROR(C20/-C21,0) -> 0.40338638 | E22: Average win divided by average loss. Above 1 = winners bigger than losers.
B23: Break-even win rate needed | C23: =IFERROR(-C21/(C20-C21),0) -> 0.71256214 | D23: =IF(C23<C19,"Achieved","Not achieved") -> Not achieved | E23: With these win/loss sizes you need at least this win rate just to break even.
B24: Profit factor | C24: =IFERROR(SUMIF(Trades!$W$2:$W$1846,">0")/-SUMIF(Trades!$W$2:$W$1846,"<0"),0) -> 0.99033621 | D24: =IF(C24>=1.3,"Good",IF(C24>=1,"Weak","Losing")) -> Losing | E24: Gross profit / gross loss. Below 1 = losing system. Aim for 1.3+.
B25: Expectancy per trade | C25: =IFERROR(C10/C16,0) -> -0.10165854 | E25: What one trade earns on average, after slippage.
B26: RISK vs REALITY
B27: Average planned risk per trade | C27: =AVERAGE(Trades!$N$2:$N$1846) -> 36.126829 | E27: SL distance x lots x 100 oz: what the EA meant to risk (about 1%).
B28: Average SL distance $ | C28: =AVERAGE(Trades!$M$2:$M$1846) -> 6 | E28: How far the stop loss was from the order price, in gold dollars.
B29: Average entry slippage $ | C29: =AVERAGE(Trades!$K$2:$K$1846) -> 0.18888347 | E29: How much worse than the order price the stop order filled (spread + slippage).
B30: Slippage as % of the stop | C30: =IFERROR(C29/C28,0) -> 0.031480578 | D30: =IF(C30>0.2,"Too high","OK") -> OK | E30: Share of the stop eaten up before the trade even starts.
B31: Average R on losing trades | C31: =IFERROR(AVERAGEIF(Trades!$Y$2:$Y$1846,"Loss",Trades!$X$2:$X$1846),0) -> -0.99427591 | D31: =IF(C31<-1.05,"Losses overshoot","OK") -> OK | E31: -1.00R = lost exactly the planned risk. Below -1R = slippage made losses bigger than planned.
B32: Losing trades that lost more than 1R | C32: =COUNTIF(Trades!$X$2:$X$1846,"<-1.05") -> 92 | E32: Losses at least 5% bigger than planned.
B33: Average R on winning trades | C33: =IFERROR(AVERAGEIF(Trades!$Y$2:$Y$1846,"Win",Trades!$X$2:$X$1846),0) -> 0.41169591 | E33: Typical winner measured in planned risk.
B34: HOLD TIME
B35: Median hold (seconds) | C35: =MEDIAN(Trades!$P$2:$P$1846) -> 2496 | D35: =IF(C35<60,"Too short","OK") -> OK | E35: Half of all trades were closed faster than this.
B36: Trades closed within 10 seconds | C36: =COUNTIF(Trades!$P$2:$P$1846,"<10") -> 39 | E36: In seconds-long trades the result is mostly spread, slippage and tick noise.
B37: Trades closed within 60 seconds | C37: =COUNTIF(Trades!$P$2:$P$1846,"<60") -> 134
B38: EXITS
B39: Exits: take profit | C39: =COUNTIF(Trades!$T$2:$T$1846,"Take profit") -> 62 | E39: Full wins at the TP.
B40: Exits: initial stop loss | C40: =COUNTIF(Trades!$T$2:$T$1846,"Initial stop loss") -> 496 | E40: Full losses.
B41: Net $ from initial-SL exits | C41: =SUMIF(Trades!$T$2:$T$1846,"Initial stop loss",Trades!$W$2:$W$1846) -> -19025.05
B42: Exits: trailing/breakeven stop | C42: =COUNTIF(Trades!$T$2:$T$1846,"Breakeven/trailing stop") -> 1204 | E42: Stop had been moved to the order price or beyond. Can still lose a little because of entry/exit slippage.
...

Sheet Monthly
A1: Month | B1: Trades | C1: Wins | D1: Losses | E1: Win rate | F1: Gross profit | G1: Gross loss | H1: Net profit | I1: Profit factor | J1: Average win | K1: Average loss | L1: Best trade | M1: Worst trade | N1: Avg R | O1: Start balance | P1: End balance | Q1: Return % | R1: Comment
A2: 2022-04 | B2: =COUNTIFS(Trades!$B$2:$B$1846,$A2) -> 34 | C2: =COUNTIFS(Trades!$B$2:$B$1846,$A2,Trades!$Y$2:$Y$1846,"Win") -> 21 | D2: =COUNTIFS(Trades!$B$2:$B$1846,$A2,Trades!$Y$2:$Y$1846,"Loss") -> 13 | E2: =IFERROR(C2/B2,0) -> 0.61764706 | F2: =SUMIFS(Trades!$W$2:$W$1846,Trades!$B$2:$B$1846,$A2,Trades!$W$2:$W$1846,">0") -> 562.92 | G2: =SUMIFS(Trades!$W$2:$W$1846,Trades!$B$2:$B$1846,$A2,Trades!$W$2:$W$1846,"<0") -> -613.81 | H2: =F2+G2 -> -50.89 | I2: =IFERROR(F2/-G2,"no losses") -> 0.91709161 | J2: =IFERROR(F2/C2,0) -> 26.805714 | K2: =IFERROR(G2/D2,0) -> -47.216154 | L2: =_xlfn.MAXIFS(Trades!$W$2:$W$1846,Trades!$B$2:$B$1846,$A2) -> 144.27 | M2: =_xlfn.MINIFS(Trades!$W$2:$W$1846,Trades!$B$2:$B$1846,$A2) -> -54.08 | N2: =IFERROR(AVERAGEIFS(Trades!$X$2:$X$1846,Trades!$B$2:$B$1846,$A2),0) -> -0.015196078 | O2: =Summary!$C$5 -> 5000 | P2: =O2+H2 -> 4949.11 | Q2: =IFERROR(H2/O2,0) -> -0.010178 | R2: =IF(H2>0,"Up month",IF(H2<0,"Down month","Flat"))&" | "&B2&" trades, "&TEXT(E2,"0%")&" won" -> Down month | 34 trades, 62% won
A3: 2022-05 | B3: =COUNTIFS(Trades!$B$2:$B$1846,$A3) -> 37 | C3: =COUNTIFS(Trades!$B$2:$B$1846,$A3,Trades!$Y$2:$Y$1846,"Win") -> 27 | D3: =COUNTIFS(Trades!$B$2:$B$1846,$A3,Trades!$Y$2:$Y$1846,"Loss") -> 10 | E3: =IFERROR(C3/B3,0) -> 0.72972973 | F3: =SUMIFS(Trades!$W$2:$W$1846,Trades!$B$2:$B$1846,$A3,Trades!$W$2:$W$1846,">0") -> 94.49 | G3: =SUMIFS(Trades!$W$2:$W$1846,Trades!$B$2:$B$1846,$A3,Trades!$W$2:$W$1846,"<0") -> -458.62 | H3: =F3+G3 -> -364.13 | I3: =IFERROR(F3/-G3,"no losses") -> 0.20603114 | J3: =IFERROR(F3/C3,0) -> 3.4996296 | K3: =IFERROR(G3/D3,0) -> -45.862 | L3: =_xlfn.MAXIFS(Trades!$W$2:$W$1846,Trades!$B$2:$B$1846,$A3) -> 4 | M3: =_xlfn.MINIFS(Trades!$W$2:$W$1846,Trades!$B$2:$B$1846,$A3) -> -48.8 | N3: =IFERROR(AVERAGEIFS(Trades!$X$2:$X$1846,Trades!$B$2:$B$1846,$A3),0) -> -0.21995495 | O3: =P2 -> 4949.11 | P3: =O3+H3 -> 4584.98 | Q3: =IFERROR(H3/O3,0) -> -0.073574845 | R3: =IF(H3>0,"Up month",IF(H3<0,"Down month","Flat"))&" | "&B3&" trades, "&TEXT(E3,"0%")&" won" -> Down month | 37 trades, 73% won
A4: 2022-06 | B4: =COUNTIFS(Trades!$B$2:$B$1846,$A4) -> 36 | C4: =COUNTIFS(Trades!$B$2:$B$1846,$A4,Trades!$Y$2:$Y$1846,"Win") -> 23 | D4: =COUNTIFS(Trades!$B$2:$B$1846,$A4,Trades!$Y$2:$Y$1846,"Loss") -> 13 | E4: =IFERROR(C4/B4,0) -> 0.63888889 | F4: =SUMIFS(Trades!$W$2:$W$1846,Trades!$B$2:$B$1846,$A4,Trades!$W$2:$W$1846,">0") -> 306.11 | G4: =SUMIFS(Trades!$W$2:$W$1846,Trades!$B$2:$B$1846,$A4,Trades!$W$2:$W$1846,"<0") -> -544.53 | H4: =F4+G4 -> -238.42 | I4: =IFERROR(F4/-G4,"no losses") -> 0.56215452 | J4: =IFERROR(F4/C4,0) -> 13.30913 | K4: =IFERROR(G4/D4,0) -> -41.886923 | L4: =_xlfn.MAXIFS(Trades!$W$2:$W$1846,Trades!$B$2:$B$1846,$A4) -> 145.11 | M4: =_xlfn.MINIFS(Trades!$W$2:$W$1846,Trades!$B$2:$B$1846,$A4) -> -48.44 | N4: =IFERROR(AVERAGEIFS(Trades!$X$2:$X$1846,Trades!$B$2:$B$1846,$A4),0) -> -0.15768519 | O4: =P3 -> 4584.98 | P4: =O4+H4 -> 4346.56 | Q4: =IFERROR(H4/O4,0) -> -0.052000227 | R4: =IF(H4>0,"Up month",IF(H4<0,"Down month","Flat"))&" | "&B4&" trades, "&TEXT(E4,"0%")&" won" -> Down month | 36 trades, 64% won
A5: 2022-07 | B5: =COUNTIFS(Trades!$B$2:$B$1846,$A5) -> 33 | C5: =COUNTIFS(Trades!$B$2:$B$1846,$A5,Trades!$Y$2:$Y$1846,"Win") -> 23 | D5: =COUNTIFS(Trades!$B$2:$B$1846,$A5,Trades!$Y$2:$Y$1846,"Loss") -> 10 | E5: =IFERROR(C5/B5,0) -> 0.6969697 | F5: =SUMIFS(Trades!$W$2:$W$1846,Trades!$B$2:$B$1846,$A5,Trades!$W$2:$W$1846,">0") -> 321.79 | G5: =SUMIFS(Trades!$W$2:$W$1846,Trades!$B$2:$B$1846,$A5,Trades!$W$2:$W$1846,"<0") -> -392.07 | H5: =F5+G5 -> -70.28 | I5: =IFERROR(F5/-G5,"no losses") -> 0.8207463 | J5: =IFERROR(F5/C5,0) -> 13.99087 | K5: =IFERROR(G5/D5,0) -> -39.207 | L5: =_xlfn.MAXIFS(Trades!$W$2:$W$1846,Trades!$B$2:$B$1846,$A5) -> 221.69 | M5: =_xlfn.MINIFS(Trades!$W$2:$W$1846,Trades!$B$2:$B$1846,$A5) -> -44.31 | N5: =IFERROR(AVERAGEIFS(Trades!$X$2:$X$1846,Trades!$B$2:$B$1846,$A5),0) -> -0.050707071 | O5: =P4 -> 4346.56 | P5: =O5+H5 -> 4276.28 | Q5: =IFERROR(H5/O5,0) -> -0.016169108 | R5: =IF(H5>0,"Up month",IF(H5<0,"Down month","Flat"))&" | "&B5&" trades, "&TEXT(E5,"0%")&" won" -> Down month | 33 trades, 70% won
A6: 2022-08 | B6: =COUNTIFS(Trades!$B$2:$B$1846,$A6) -> 38 | C6: =COUNTIFS(Trades!$B$2:$B$1846,$A6,Trades!$Y$2:$Y$1846,"Win") -> 25 | D6: =COUNTIFS(Trades!$B$2:$B$1846,$A6,Trades!$Y$2:$Y$1846,"Loss") -> 13 | E6: =IFERROR(C6/B6,0) -> 0.65789474 | F6: =SUMIFS(Trades!$W$2:$W$1846,Trades!$B$2:$B$1846,$A6,Trades!$W$2:$W$1846,">0") -> 323.38 | G6: =SUMIFS(Trades!$W$2:$W$1846,Trades!$B$2:$B$1846,$A6,Trades!$W$2:$W$1846,"<0") -> -528.13 | H6: =F6+G6 -> -204.75 | I6: =IFERROR(F6/-G6,"no losses") -> 0.61231136 | J6: =IFERROR(F6/C6,0) -> 12.9352 | K6: =IFERROR(G6/D6,0) -> -40.625385 | L6: =_xlfn.MAXIFS(Trades!$W$2:$W$1846,Trades!$B$2:$B$1846,$A6) -> 139.09 | M6: =_xlfn.MINIFS(Trades!$W$2:$W$1846,Trades!$B$2:$B$1846,$A6) -> -42.49 | N6: =IFERROR(AVERAGEIFS(Trades!$X$2:$X$1846,Trades!$B$2:$B$1846,$A6),0) -> -0.13447368 | O6: =P5 -> 4276.28 | P6: =O6+H6 -> 4071.53 | Q6: =IFERROR(H6/O6,0) -> -0.047880401 | R6: =IF(H6>0,"Up month",IF(H6<0,"Down month","Flat"))&" | "&B6&" trades, "&TEXT(E6,"0%")&" won" -> Down month | 38 trades, 66% won
A7: 2022-09 | B7: =COUNTIFS(Trades!$B$2:$B$1846,$A7) -> 35 | C7: =COUNTIFS(Trades!$B$2:$B$1846,$A7,Trades!$Y$2:$Y$1846,"Win") -> 25 | D7: =COUNTIFS(Trades!$B$2:$B$1846,$A7,Trades!$Y$2:$Y$1846,"Loss") -> 10 | E7: =IFERROR(C7/B7,0) -> 0.71428571 | F7: =SUMIFS(Trades!$W$2:$W$1846,Trades!$B$2:$B$1846,$A7,Trades!$W$2:$W$1846,">0") -> 132.24 | G7: =SUMIFS(Trades!$W$2:$W$1846,Trades!$B$2:$B$1846,$A7,Trades!$W$2:$W$1846,"<0") -> -353.76 | H7: =F7+G7 -> -221.52 | I7: =IFERROR(F7/-G7,"no losses") -> 0.37381275 | J7: =IFERROR(F7/C7,0) -> 5.2896 | K7: =IFERROR(G7/D7,0) -> -35.376 | L7: =_xlfn.MAXIFS(Trades!$W$2:$W$1846,Trades!$B$2:$B$1846,$A7) -> 57.54 | M7: =_xlfn.MINIFS(Trades!$W$2:$W$1846,Trades!$B$2:$B$1846,$A7) -> -50.82 | N7: =IFERROR(AVERAGEIFS(Trades!$X$2:$X$1846,Trades!$B$2:$B$1846,$A7),0) -> -0.17580952 | O7: =P6 -> 4071.53 | P7: =O7+H7 -> 3850.01 | Q7: =IFERROR(H7/O7,0) -> -0.054407066 | R7: =IF(H7>0,"Up month",IF(H7<0,"Down month","Flat"))&" | "&B7&" trades, "&TEXT(E7,"0%")&" won" -> Down month | 35 trades, 71% won
A8: 2022-10 | B8: =COUNTIFS(Trades!$B$2:$B$1846,$A8) -> 29 | C8: =COUNTIFS(Trades!$B$2:$B$1846,$A8,Trades!$Y$2:$Y$1846,"Win") -> 23 | D8: =COUNTIFS(Trades!$B$2:$B$1846,$A8,Trades!$Y$2:$Y$1846,"Loss") -> 6 | E8: =IFERROR(C8/B8,0) -> 0.79310345 | F8: =SUMIFS(Trades!$W$2:$W$1846,Trades!$B$2:$B$1846,$A8,Trades!$W$2:$W$1846,">0") -> 444.84 | G8: =SUMIFS(Trades!$W$2:$W$1846,Trades!$B$2:$B$1846,$A8,Trades!$W$2:$W$1846,"<0") -> -217.44 | H8: =F8+G8 -> 227.4 | I8: =IFERROR(F8/-G8,"no losses") -> 2.0458057 | J8: =IFERROR(F8/C8,0) -> 19.34087 | K8: =IFERROR(G8/D8,0) -> -36.24 | L8: =_xlfn.MAXIFS(Trades!$W$2:$W$1846,Trades!$B$2:$B$1846,$A8) -> 130.32 | M8: =_xlfn.MINIFS(Trades!$W$2:$W$1846,Trades!$B$2:$B$1846,$A8) -> -36.6 | N8: =IFERROR(AVERAGEIFS(Trades!$X$2:$X$1846,Trades!$B$2:$B$1846,$A8),0) -> 0.21781609 | O8: =P7 -> 3850.01 | P8: =O8+H8 -> 4077.41 | Q8: =IFERROR(H8/O8,0) -> 0.059064782 | R8: =IF(H8>0,"Up month",IF(H8<0,"Down month","Flat"))&" | "&B8&" trades, "&TEXT(E8,"0%")&" won" -> Up month | 29 trades, 79% won
A9: 2022-11 | B9: =COUNTIFS(Trades!$B$2:$B$1846,$A9) -> 37 | C9: =COUNTIFS(Trades!$B$2:$B$1846,$A9,Trades!$Y$2:$Y$1846,"Win") -> 30 | D9: =COUNTIFS(Trades!$B$2:$B$1846,$A9,Trades!$Y$2:$Y$1846,"Loss") -> 7 | E9: =IFERROR(C9/B9,0) -> 0.81081081 | F9: =SUMIFS(Trades!$W$2:$W$1846,Trades!$B$2:$B$1846,$A9,Trades!$W$2:$W$1846,">0") -> 680.5 | G9: =SUMIFS(Trades!$W$2:$W$1846,Trades!$B$2:$B$1846,$A9,Trades!$W$2:$W$1846,"<0") -> -278.94 | H9: =F9+G9 -> 401.56 | I9: =IFERROR(F9/-G9,"no losses") -> 2.4395927 | J9: =IFERROR(F9/C9,0) -> 22.683333 | K9: =IFERROR(G9/D9,0) -> -39.848571 | L9: =_xlfn.MAXIFS(Trades!$W$2:$W$1846,Trades!$B$2:$B$1846,$A9) -> 208.88 | M9: =_xlfn.MINIFS(Trades!$W$2:$W$1846,Trades!$B$2:$B$1846,$A9) -> -42.7 | N9: =IFERROR(AVERAGEIFS(Trades!$X$2:$X$1846,Trades!$B$2:$B$1846,$A9),0) -> 0.28851351 | O9: =P8 -> 4077.41 | P9: =O9+H9 -> 4478.97 | Q9: =IFERROR(H9/O9,0) -> 0.098484087 | R9: =IF(H9>0,"Up month",IF(H9<0,"Down month","Flat"))&" | "&B9&" trades, "&TEXT(E9,"0%")&" won" -> Up month | 37 trades, 81% won
A10: 2022-12 | B10: =COUNTIFS(Trades!$B$2:$B$1846,$A10) -> 32 | C10: =COUNTIFS(Trades!$B$2:$B$1846,$A10,Trades!$Y$2:$Y$1846,"Win") -> 27 | D10: =COUNTIFS(Trades!$B$2:$B$1846,$A10,Trades!$Y$2:$Y$1846,"Loss") -> 5 | E10: =IFERROR(C10/B10,0) -> 0.84375 | F10: =SUMIFS(Trades!$W$2:$W$1846,Trades!$B$2:$B$1846,$A10,Trades!$W$2:$W$1846,">0") -> 499.59 | G10: =SUMIFS(Trades!$W$2:$W$1846,Trades!$B$2:$B$1846,$A10,Trades!$W$2:$W$1846,"<0") -> -211.96 | H10: =F10+G10 -> 287.63 | I10: =IFERROR(F10/-G10,"no losses") -> 2.3570013 | J10: =IFERROR(F10/C10,0) -> 18.503333 | K10: =IFERROR(G10/D10,0) -> -42.392 | L10: =_xlfn.MAXIFS(Trades!$W$2:$W$1846,Trades!$B$2:$B$1846,$A10) -> 162.89 | M10: =_xlfn.MINIFS(Trades!$W$2:$W$1846,Trades!$B$2:$B$1846,$A10) -> -42.84 | N10: =IFERROR(AVERAGEIFS(Trades!$X$2:$X$1846,Trades!$B$2:$B$1846,$A10),0) -> 0.21401042 | O10: =P9 -> 4478.97 | P10: =O10+H10 -> 4766.6 | Q10: =IFERROR(H10/O10,0) -> 0.064217889 | R10: =IF(H10>0,"Up month",IF(H10<0,"Down month","Flat"))&" | "&B10&" trades, "&TEXT(E10,"0%")&" won" -> Up month | 32 trades, 84% won
A11: 2023-01 | B11: =COUNTIFS(Trades!$B$2:$B$1846,$A11) -> 33 | C11: =COUNTIFS(Trades!$B$2:$B$1846,$A11,Trades!$Y$2:$Y$1846,"Win") -> 25 | D11: =COUNTIFS(Trades!$B$2:$B$1846,$A11,Trades!$Y$2:$Y$1846,"Loss") -> 8 | E11: =IFERROR(C11/B11,0) -> 0.75757576 | F11: =SUMIFS(Trades!$W$2:$W$1846,Trades!$B$2:$B$1846,$A11,Trades!$W$2:$W$1846,">0") -> 150.71 | G11: =SUMIFS(Trades!$W$2:$W$1846,Trades!$B$2:$B$1846,$A11,Trades!$W$2:$W$1846,"<0") -> -349.23 | H11: =F11+G11 -> -198.52 | I11: =IFERROR(F11/-G11,"no losses") -> 0.43154941 | J11: =IFERROR(F11/C11,0) -> 6.0284 | K11: =IFERROR(G11/D11,0) -> -43.65375 | L11: =_xlfn.MAXIFS(Trades!$W$2:$W$1846,Trades!$B$2:$B$1846,$A11) -> 62.65 | M11: =_xlfn.MINIFS(Trades!$W$2:$W$1846,Trades!$B$2:$B$1846,$A11) -> -48.3 | N11: =IFERROR(AVERAGEIFS(Trades!$X$2:$X$1846,Trades!$B$2:$B$1846,$A11),0) -> -0.14323232 | O11: =P10 -> 4766.6 | P11: =O11+H11 -> 4568.08 | Q11: =IFERROR(H11/O11,0) -> -0.041648135 | R11: =IF(H11>0,"Up month",IF(H11<0,"Down month","Flat"))&" | "&B11&" trades, "&TEXT(E11,"0%")&" won" -> Down month | 33 trades, 76% won
A12: 2023-02 | B12: =COUNTIFS(Trades!$B$2:$B$1846,$A12) -> 35 | C12: =COUNTIFS(Trades!$B$2:$B$1846,$A12,Trades!$Y$2:$Y$1846,"Win") -> 23 | D12: =COUNTIFS(Trades!$B$2:$B$1846,$A12,Trades!$Y$2:$Y$1846,"Loss") -> 12 | E12: =IFERROR(C12/B12,0) -> 0.65714286 | F12: =SUMIFS(Trades!$W$2:$W$1846,Trades!$B$2:$B$1846,$A12,Trades!$W$2:$W$1846,">0") -> 127.26 | G12: =SUMIFS(Trades!$W$2:$W$1846,Trades!$B$2:$B$1846,$A12,Trades!$W$2:$W$1846,"<0") -> -474.6 | H12: =F12+G12 -> -347.34 | I12: =IFERROR(F12/-G12,"no losses") -> 0.26814159 | J12: =IFERROR(F12/C12,0) -> 5.5330435 | K12: =IFERROR(G12/D12,0) -> -39.55 | L12: =_xlfn.MAXIFS(Trades!$W$2:$W$1846,Trades!$B$2:$B$1846,$A12) -> 54.18 | M12: =_xlfn.MINIFS(Trades!$W$2:$W$1846,Trades!$B$2:$B$1846,$A12) -> -43.54 | N12: =IFERROR(AVERAGEIFS(Trades!$X$2:$X$1846,Trades!$B$2:$B$1846,$A12),0) -> -0.23628571 | O12: =P11 -> 4568.08 | P12: =O12+H12 -> 4220.74 | Q12: =IFERROR(H12/O12,0) -> -0.076036322 | R12: =IF(H12>0,"Up month",IF(H12<0,"Down month","Flat"))&" | "&B12&" trades, "&TEXT(E12,"0%")&" won" -> Down month | 35 trades, 66% won
A13: 2023-03 | B13: =COUNTIFS(Trades!$B$2:$B$1846,$A13) -> 31 | C13: =COUNTIFS(Trades!$B$2:$B$1846,$A13,Trades!$Y$2:$Y$1846,"Win") -> 23 | D13: =COUNTIFS(Trades!$B$2:$B$1846,$A13,Trades!$Y$2:$Y$1846,"Loss") -> 8 | E13: =IFERROR(C13/B13,0) -> 0.74193548 | F13: =SUMIFS(Trades!$W$2:$W$1846,Trades!$B$2:$B$1846,$A13,Trades!$W$2:$W$1846,">0") -> 246.46 | G13: =SUMIFS(Trades!$W$2:$W$1846,Trades!$B$2:$B$1846,$A13,Trades!$W$2:$W$1846,"<0") -> -324.82 | H13: =F13+G13 -> -78.36 | I13: =IFERROR(F13/-G13,"no losses") -> 0.7587587 | J13: =IFERROR(F13/C13,0) -> 10.715652 | K13: =IFERROR(G13/D13,0) -> -40.6025 | L13: =_xlfn.MAXIFS(Trades!$W$2:$W$1846,Trades!$B$2:$B$1846,$A13) -> 179.76 | M13: =_xlfn.MINIFS(Trades!$W$2:$W$1846,Trades!$B$2:$B$1846,$A13) -> -45.6 | N13: =IFERROR(AVERAGEIFS(Trades!$X$2:$X$1846,Trades!$B$2:$B$1846,$A13),0) -> -0.052580645 | O13: =P12 -> 4220.74 | P13: =O13+H13 -> 4142.38 | Q13: =IFERROR(H13/O13,0) -> -0.018565465 | R13: =IF(H13>0,"Up month",IF(H13<0,"Down month","Flat"))&" | "&B13&" trades, "&TEXT(E13,"0%")&" won" -> Down month | 31 trades, 74% won
A14: 2023-04 | B14: =COUNTIFS(Trades!$B$2:$B$1846,$A14) -> 30 | C14: =COUNTIFS(Trades!$B$2:$B$1846,$A14,Trades!$Y$2:$Y$1846,"Win") -> 26 | D14: =COUNTIFS(Trades!$B$2:$B$1846,$A14,Trades!$Y$2:$Y$1846,"Loss") -> 4 | E14: =IFERROR(C14/B14,0) -> 0.86666667 | F14: =SUMIFS(Trades!$W$2:$W$1846,Trades!$B$2:$B$1846,$A14,Trades!$W$2:$W$1846,">0") -> 128.1 | G14: =SUMIFS(Trades!$W$2:$W$1846,Trades!$B$2:$B$1846,$A14,Trades!$W$2:$W$1846,"<0") -> -149.58 | H14: =F14+G14 -> -21.48 | I14: =IFERROR(F14/-G14,"no losses") -> 0.85639791 | J14: =IFERROR(F14/C14,0) -> 4.9269231 | K14: =IFERROR(G14/D14,0) -> -37.395 | L14: =_xlfn.MAXIFS(Trades!$W$2:$W$1846,Trades!$B$2:$B$1846,$A14) -> 45.18 | M14: =_xlfn.MINIFS(Trades!$W$2:$W$1846,Trades!$B$2:$B$1846,$A14) -> -40.08 | N14: =IFERROR(AVERAGEIFS(Trades!$X$2:$X$1846,Trades!$B$2:$B$1846,$A14),0) -> -0.019888889 | O14: =P13 -> 4142.38 | P14: =O14+H14 -> 4120.9 | Q14: =IFERROR(H14/O14,0) -> -0.0051854248 | R14: =IF(H14>0,"Up month",IF(H14<0,"Down month","Flat"))&" | "&B14&" trades, "&TEXT(E14,"0%")&" won" -> Down month | 30 trades, 87% won
... A55: 2026-09 | B55: =COUNTIFS(Trades!$B$2:$B$1846,$A55) -> 34 | C55: =COUNTIFS(Trades!$B$2:$B$1846,$A55,Trades!$Y$2:$Y$1846,"Win") -> 24 | D55: =COUNTIFS(Trades!$B$2:$B$1846,$A55,Trades!$Y$2:$Y$1846,"Loss") -> 10 | E55: =IFERROR(C55/B55,0) -> 0.70588235 | F55: =SUMIFS(Trades!$W$2:$W$1846,Trades!$B$2:$B$1846,$A55,Trades!$W$2:$W$1846,">0") -> 695.57 | G55: =SUMIFS(Trades!$W$2:$W$1846,Trades!$B$2:$B$1846,$A55,Trades!$W$2:$W$1846,"<0") -> -489 | H55: =F55+G55 -> 206.57 | I55: =IFERROR(F55/-G55,"no losses") -> 1.4224335 | J55: =IFERROR(F55/C55,0) -> 28.982083 | K55: =IFERROR(G55/D55,0) -> -48.9 | L55: =_xlfn.MAXIFS(Trades!$W$2:$W$1846,Trades!$B$2:$B$1846,$A55) -> 213.85 | M55: =_xlfn.MINIFS(Trades!$W$2:$W$1846,Trades!$B$2:$B$1846,$A55) -> -99.26 | N55: =IFERROR(AVERAGEIFS(Trades!$X$2:$X$1846,Trades!$B$2:$B$1846,$A55),0) -> 0.15529412 | O55: =P54 -> 4605.87 | P55: =O55+H55 -> 4812.44 | Q55: =IFERROR(H55/O55,0) -> 0.04484929 | R55: =IF(H55>0,"Up month",IF(H55<0,"Down month","Flat"))&" | "&B55&" trades, "&TEXT(E55,"0%")&" won" -> Up month | 34 trades, 71% won
A56: TOTAL | B56: =SUM(B2:B55) -> 1845 | C56: =SUM(C2:C55) -> 1311 | D56: =SUM(D2:D55) -> 534 | E56: =IFERROR(C56/B56,0) -> 0.71056911 | F56: =SUM(F2:F55) -> 19220.98 | G56: =SUM(G2:G55) -> -19408.54 | H56: =SUM(H2:H55) -> -187.56 | I56: =IFERROR(F56/-G56,0) -> 0.99033621 | P56: =P55 -> 4812.44 | Q56: =IFERROR(H56/O2,0) -> -0.037512 | R56: =COUNTIF(H2:H55,">0")&" up months / "&COUNTIF(H2:H55,"<0")&" down months" -> 21 up months / 33 down months
A58: Blue = up month, orange = down month.

Sheet Breakdown
A1: Where the money is made and lost
A3: By side | G3: Is one direction worse than the other?
A4: side | B4: Trades | C4: Win rate | D4: Net profit | E4: Avg per trade | F4: Avg R
A5: BUY | B5: =COUNTIFS(Trades!$F$2:$F$1846,$A5) -> 951 | C5: =IFERROR(COUNTIFS(Trades!$F$2:$F$1846,$A5,Trades!$Y$2:$Y$1846,"Win")/B5,0) -> 0.74237645 | D5: =SUMIFS(Trades!$W$2:$W$1846,Trades!$F$2:$F$1846,$A5) -> 3145.18 | E5: =IFERROR(D5/B5,0) -> 3.3072345 | F5: =IFERROR(AVERAGEIFS(Trades!$X$2:$X$1846,Trades!$F$2:$F$1846,$A5),0) -> 0.099616193
A6: SELL | B6: =COUNTIFS(Trades!$F$2:$F$1846,$A6) -> 894 | C6: =IFERROR(COUNTIFS(Trades!$F$2:$F$1846,$A6,Trades!$Y$2:$Y$1846,"Win")/B6,0) -> 0.67673378 | D6: =SUMIFS(Trades!$W$2:$W$1846,Trades!$F$2:$F$1846,$A6) -> -3332.74 | E6: =IFERROR(D6/B6,0) -> -3.7278971 | F6: =IFERROR(AVERAGEIFS(Trades!$X$2:$X$1846,Trades!$F$2:$F$1846,$A6),0) -> -0.096135347
A7: Total | B7: =SUM(B5:B6) -> 1845 | D7: =SUM(D5:D6) -> -187.56
A9: By exit reason | G9: Avg R on 'Initial stop loss' below -1R means the stop filled worse than planned (slippage).
A10: exit reason | B10: Trades | C10: Win rate | D10: Net profit | E10: Avg per trade | F10: Avg R
A11: Take profit | B11: =COUNTIFS(Trades!$T$2:$T$1846,$A11) -> 62 | C11: =IFERROR(COUNTIFS(Trades!$T$2:$T$1846,$A11,Trades!$Y$2:$Y$1846,"Win")/B11,0) -> 1 | D11: =SUMIFS(Trades!$W$2:$W$1846,Trades!$T$2:$T$1846,$A11) -> 11121.25 | E11: =IFERROR(D11/B11,0) -> 179.375 | F11: =IFERROR(AVERAGEIFS(Trades!$X$2:$X$1846,Trades!$T$2:$T$1846,$A11),0) -> 4.9646237
A12: Initial stop loss | B12: =COUNTIFS(Trades!$T$2:$T$1846,$A12) -> 496 | C12: =IFERROR(COUNTIFS(Trades!$T$2:$T$1846,$A12,Trades!$Y$2:$Y$1846,"Win")/B12,0) -> 0 | D12: =SUMIFS(Trades!$W$2:$W$1846,Trades!$T$2:$T$1846,$A12) -> -19025.05 | E12: =IFERROR(D12/B12,0) -> -38.356956 | F12: =IFERROR(AVERAGEIFS(Trades!$X$2:$X$1846,Trades!$T$2:$T$1846,$A12),0) -> -1.0496304
A13: Breakeven/trailing stop | B13: =COUNTIFS(Trades!$T$2:$T$1846,$A13) -> 1204 | C13: =IFERROR(COUNTIFS(Trades!$T$2:$T$1846,$A13,Trades!$Y$2:$Y$1846,"Win")/B13,0) -> 0.97674419 | D13: =SUMIFS(Trades!$W$2:$W$1846,Trades!$T$2:$T$1846,$A13) -> 2954.52 | E13: =IFERROR(D13/B13,0) -> 2.4539203 | F13: =IFERROR(AVERAGEIFS(Trades!$X$2:$X$1846,Trades!$T$2:$T$1846,$A13),0) -> 0.068354097
A14: Moved stop (below entry) | B14: =COUNTIFS(Trades!$T$2:$T$1846,$A14) -> 0 | C14: =IFERROR(COUNTIFS(Trades!$T$2:$T$1846,$A14,Trades!$Y$2:$Y$1846,"Win")/B14,0) -> 0 | D14: =SUMIFS(Trades!$W$2:$W$1846,Trades!$T$2:$T$1846,$A14) -> 0 | E14: =IFERROR(D14/B14,0) -> 0 | F14: =IFERROR(AVERAGEIFS(Trades!$X$2:$X$1846,Trades!$T$2:$T$1846,$A14),0) -> 0
A15: Closed by EA (no SL) | B15: =COUNTIFS(Trades!$T$2:$T$1846,$A15) -> 83 | C15: =IFERROR(COUNTIFS(Trades!$T$2:$T$1846,$A15,Trades!$Y$2:$Y$1846,"Win")/B15,0) -> 0.87951807 | D15: =SUMIFS(Trades!$W$2:$W$1846,Trades!$T$2:$T$1846,$A15) -> 4761.72 | E15: =IFERROR(D15/B15,0) -> 57.37012 | F15: =IFERROR(AVERAGEIFS(Trades!$X$2:$X$1846,Trades!$T$2:$T$1846,$A15),0) -> 1.6783333
A16: Total | B16: =SUM(B11:B15) -> 1845 | D16: =SUM(D11:D15) -> -187.56
A18: By hold time | G18: Trades lasting seconds are decided by spread and tick noise, not by the strategy idea.
A19: hold time | B19: Trades | C19: Win rate | D19: Net profit | E19: Avg per trade | F19: Avg R
A20: a) <10s | B20: =COUNTIFS(Trades!$Q$2:$Q$1846,$A20) -> 39 | C20: =IFERROR(COUNTIFS(Trades!$Q$2:$Q$1846,$A20,Trades!$Y$2:$Y$1846,"Win")/B20,0) -> 0.69230769 | D20: =SUMIFS(Trades!$W$2:$W$1846,Trades!$Q$2:$Q$1846,$A20) -> -357.5 | E20: =IFERROR(D20/B20,0) -> -9.1666667 | F20: =IFERROR(AVERAGEIFS(Trades!$X$2:$X$1846,Trades!$Q$2:$Q$1846,$A20),0) -> -0.22149573
A21: b) 10-60s | B21: =COUNTIFS(Trades!$Q$2:$Q$1846,$A21) -> 95 | C21: =IFERROR(COUNTIFS(Trades!$Q$2:$Q$1846,$A21,Trades!$Y$2:$Y$1846,"Win")/B21,0) -> 0.67368421 | D21: =SUMIFS(Trades!$W$2:$W$1846,Trades!$Q$2:$Q$1846,$A21) -> -807.29 | E21: =IFERROR(D21/B21,0) -> -8.4977895 | F21: =IFERROR(AVERAGEIFS(Trades!$X$2:$X$1846,Trades!$Q$2:$Q$1846,$A21),0) -> -0.21633333
A22: c) 1-10min | B22: =COUNTIFS(Trades!$Q$2:$Q$1846,$A22) -> 377 | C22: =IFERROR(COUNTIFS(Trades!$Q$2:$Q$1846,$A22,Trades!$Y$2:$Y$1846,"Win")/B22,0) -> 0.74005305 | D22: =SUMIFS(Trades!$W$2:$W$1846,Trades!$Q$2:$Q$1846,$A22) -> -2644.58 | E22: =IFERROR(D22/B22,0) -> -7.0148011 | F22: =IFERROR(AVERAGEIFS(Trades!$X$2:$X$1846,Trades!$Q$2:$Q$1846,$A22),0) -> -0.17763926
A23: d) >10min | B23: =COUNTIFS(Trades!$Q$2:$Q$1846,$A23) -> 1334 | C23: =IFERROR(COUNTIFS(Trades!$Q$2:$Q$1846,$A23,Trades!$Y$2:$Y$1846,"Win")/B23,0) -> 0.7053973 | D23: =SUMIFS(Trades!$W$2:$W$1846,Trades!$Q$2:$Q$1846,$A23) -> 3621.81 | E23: =IFERROR(D23/B23,0) -> 2.715 | F23: =IFERROR(AVERAGEIFS(Trades!$X$2:$X$1846,Trades!$Q$2:$Q$1846,$A23),0) -> 0.078673163
A24: Total | B24: =SUM(B20:B23) -> 1845 | D24: =SUM(D20:D23) -> -187.56
A26: By weekday (entry) | G26: Day of the week the trade was entered (server time).
A27: weekday | B27: Trades | C27: Win rate | D27: Net profit | E27: Avg per trade | F27: Avg R
A28: Mon | B28: =COUNTIFS(Trades!$D$2:$D$1846,$A28) -> 324 | C28: =IFERROR(COUNTIFS(Trades!$D$2:$D$1846,$A28,Trades!$Y$2:$Y$1846,"Win")/B28,0) -> 0.7191358 | D28: =SUMIFS(Trades!$W$2:$W$1846,Trades!$D$2:$D$1846,$A28) -> 1068.03 | E28: =IFERROR(D28/B28,0) -> 3.2963889 | F28: =IFERROR(AVERAGEIFS(Trades!$X$2:$X$1846,Trades!$D$2:$D$1846,$A28),0) -> 0.094984568
A29: Tue | B29: =COUNTIFS(Trades!$D$2:$D$1846,$A29) -> 374 | C29: =IFERROR(COUNTIFS(Trades!$D$2:$D$1846,$A29,Trades!$Y$2:$Y$1846,"Win")/B29,0) -> 0.72994652 | D29: =SUMIFS(Trades!$W$2:$W$1846,Trades!$D$2:$D$1846,$A29) -> 268.96 | E29: =IFERROR(D29/B29,0) -> 0.71914439 | F29: =IFERROR(AVERAGEIFS(Trades!$X$2:$X$1846,Trades!$D$2:$D$1846,$A29),0) -> 0.03092246
A30: Wed | B30: =COUNTIFS(Trades!$D$2:$D$1846,$A30) -> 385 | C30: =IFERROR(COUNTIFS(Trades!$D$2:$D$1846,$A30,Trades!$Y$2:$Y$1846,"Win")/B30,0) -> 0.6961039 | D30: =SUMIFS(Trades!$W$2:$W$1846,Trades!$D$2:$D$1846,$A30) -> -1470.61 | E30: =IFERROR(D30/B30,0) -> -3.8197662 | F30: =IFERROR(AVERAGEIFS(Trades!$X$2:$X$1846,Trades!$D$2:$D$1846,$A30),0) -> -0.10136797
A31: Thu | B31: =COUNTIFS(Trades!$D$2:$D$1846,$A31) -> 386 | C31: =IFERROR(COUNTIFS(Trades!$D$2:$D$1846,$A31,Trades!$Y$2:$Y$1846,"Win")/B31,0) -> 0.69170984 | D31: =SUMIFS(Trades!$W$2:$W$1846,Trades!$D$2:$D$1846,$A31) -> -581.98 | E31: =IFERROR(D31/B31,0) -> -1.5077202 | F31: =IFERROR(AVERAGEIFS(Trades!$X$2:$X$1846,Trades!$D$2:$D$1846,$A31),0) -> -0.036765976
A32: Fri | B32: =COUNTIFS(Trades!$D$2:$D$1846,$A32) -> 376 | C32: =IFERROR(COUNTIFS(Trades!$D$2:$D$1846,$A32,Trades!$Y$2:$Y$1846,"Win")/B32,0) -> 0.71808511 | D32: =SUMIFS(Trades!$W$2:$W$1846,Trades!$D$2:$D$1846,$A32) -> 528.04 | E32: =IFERROR(D32/B32,0) -> 1.4043617 | F32: =IFERROR(AVERAGEIFS(Trades!$X$2:$X$1846,Trades!$D$2:$D$1846,$A32),0) -> 0.052309397
A33: Total | B33: =SUM(B28:B32) -> 1845 | D33: =SUM(D28:D32) -> -187.56
A35: By entry hour (server time) | G35: Server hour of entry. On a UTC+2/+3 broker: 01-09 = Asian session, 10-18 = London, 15-23 = New York.
A36: entry hour | B36: Trades | C36: Win rate | D36: Net profit | E36: Avg per trade | F36: Avg R
A37: 0 | B37: =COUNTIFS(Trades!$E$2:$E$1846,$A37) -> 0 | C37: =IFERROR(COUNTIFS(Trades!$E$2:$E$1846,$A37,Trades!$Y$2:$Y$1846,"Win")/B37,0) -> 0 | D37: =SUMIFS(Trades!$W$2:$W$1846,Trades!$E$2:$E$1846,$A37) -> 0 | E37: =IFERROR(D37/B37,0) -> 0 | F37: =IFERROR(AVERAGEIFS(Trades!$X$2:$X$1846,Trades!$E$2:$E$1846,$A37),0) -> 0
A38: 1 | B38: =COUNTIFS(Trades!$E$2:$E$1846,$A38) -> 43 | C38: =IFERROR(COUNTIFS(Trades!$E$2:$E$1846,$A38,Trades!$Y$2:$Y$1846,"Win")/B38,0) -> 0.79069767 | D38: =SUMIFS(Trades!$W$2:$W$1846,Trades!$E$2:$E$1846,$A38) -> 143.76 | E38: =IFERROR(D38/B38,0) -> 3.3432558 | F38: =IFERROR(AVERAGEIFS(Trades!$X$2:$X$1846,Trades!$E$2:$E$1846,$A38),0) -> 0.088953488
A39: 2 | B39: =COUNTIFS(Trades!$E$2:$E$1846,$A39) -> 77 | C39: =IFERROR(COUNTIFS(Trades!$E$2:$E$1846,$A39,Trades!$Y$2:$Y$1846,"Win")/B39,0) -> 0.68831169 | D39: =SUMIFS(Trades!$W$2:$W$1846,Trades!$E$2:$E$1846,$A39) -> 157.26 | E39: =IFERROR(D39/B39,0) -> 2.0423377 | F39: =IFERROR(AVERAGEIFS(Trades!$X$2:$X$1846,Trades!$E$2:$E$1846,$A39),0) -> 0.092727273
A40: 3 | B40: =COUNTIFS(Trades!$E$2:$E$1846,$A40) -> 92 | C40: =IFERROR(COUNTIFS(Trades!$E$2:$E$1846,$A40,Trades!$Y$2:$Y$1846,"Win")/B40,0) -> 0.72826087 | D40: =SUMIFS(Trades!$W$2:$W$1846,Trades!$E$2:$E$1846,$A40) -> 568.14 | E40: =IFERROR(D40/B40,0) -> 6.1754348 | F40: =IFERROR(AVERAGEIFS(Trades!$X$2:$X$1846,Trades!$E$2:$E$1846,$A40),0) -> 0.15856884
A41: 4 | B41: =COUNTIFS(Trades!$E$2:$E$1846,$A41) -> 79 | C41: =IFERROR(COUNTIFS(Trades!$E$2:$E$1846,$A41,Trades!$Y$2:$Y$1846,"Win")/B41,0) -> 0.69620253 | D41: =SUMIFS(Trades!$W$2:$W$1846,Trades!$E$2:$E$1846,$A41) -> -3.24 | E41: =IFERROR(D41/B41,0) -> -0.041012658 | F41: =IFERROR(AVERAGEIFS(Trades!$X$2:$X$1846,Trades!$E$2:$E$1846,$A41),0) -> 0.053924051
A42: 5 | B42: =COUNTIFS(Trades!$E$2:$E$1846,$A42) -> 51 | C42: =IFERROR(COUNTIFS(Trades!$E$2:$E$1846,$A42,Trades!$Y$2:$Y$1846,"Win")/B42,0) -> 0.76470588 | D42: =SUMIFS(Trades!$W$2:$W$1846,Trades!$E$2:$E$1846,$A42) -> 215.84 | E42: =IFERROR(D42/B42,0) -> 4.2321569 | F42: =IFERROR(AVERAGEIFS(Trades!$X$2:$X$1846,Trades!$E$2:$E$1846,$A42),0) -> 0.10643791
A43: 6 | B43: =COUNTIFS(Trades!$E$2:$E$1846,$A43) -> 28 | C43: =IFERROR(COUNTIFS(Trades!$E$2:$E$1846,$A43,Trades!$Y$2:$Y$1846,"Win")/B43,0) -> 0.64285714 | D43: =SUMIFS(Trades!$W$2:$W$1846,Trades!$E$2:$E$1846,$A43) -> -32.92 | E43: =IFERROR(D43/B43,0) -> -1.1757143 | F43: =IFERROR(AVERAGEIFS(Trades!$X$2:$X$1846,Trades!$E$2:$E$1846,$A43),0) -> -0.045059524
A44: 7 | B44: =COUNTIFS(Trades!$E$2:$E$1846,$A44) -> 31 | C44: =IFERROR(COUNTIFS(Trades!$E$2:$E$1846,$A44,Trades!$Y$2:$Y$1846,"Win")/B44,0) -> 0.70967742 | D44: =SUMIFS(Trades!$W$2:$W$1846,Trades!$E$2:$E$1846,$A44) -> -157.96 | E44: =IFERROR(D44/B44,0) -> -5.0954839 | F44: =IFERROR(AVERAGEIFS(Trades!$X$2:$X$1846,Trades!$E$2:$E$1846,$A44),0) -> -0.12295699
A45: 8 | B45: =COUNTIFS(Trades!$E$2:$E$1846,$A45) -> 40 | C45: =IFERROR(COUNTIFS(Trades!$E$2:$E$1846,$A45,Trades!$Y$2:$Y$1846,"Win")/B45,0) -> 0.8 | D45: =SUMIFS(Trades!$W$2:$W$1846,Trades!$E$2:$E$1846,$A45) -> 521.77 | E45: =IFERROR(D45/B45,0) -> 13.04425 | F45: =IFERROR(AVERAGEIFS(Trades!$X$2:$X$1846,Trades!$E$2:$E$1846,$A45),0) -> 0.39416667
...

Sheet Trades
A1: # | B1: Month | C1: Entry time (server) | D1: Weekday | E1: Entry hour | F1: Side | G1: Setup | H1: Lots | I1: Order price (planned entry) | J1: Filled entry | K1: Entry slippage $ | L1: Initial SL | M1: SL distance $ | N1: Planned risk $ | O1: Exit time | P1: Hold (sec) | Q1: Hold bucket | R1: Stop level hit | S1: Exit price | T1: Exit reason | U1: Exit slippage $ | V1: Price move $ | W1: Profit $ | X1: R multiple | Y1: Result | Z1: Balance after | AA1: Peak balance | AB1: Drawdown $ | AC1: Drawdown % | AD1: What happened
A2: 1 | B2: 2022-04 | C2: 44652.379 | D2: Fri | E2: 9 | F2: BUY | G2: RANGE_B | H2: 0.08 | I2: 1939.36 | J2: 1939.36 | K2: =IF(F2="BUY",J2-I2,I2-J2) -> 0 | L2: 1933.36 | M2: =ABS(I2-L2) -> 6 | N2: =M2*H2*Summary!$C$6 -> 48 | O2: 44652.403 | P2: =ROUND((O2-C2)*86400,0) -> 2078 | Q2: =IF(P2<10,"a) <10s",IF(P2<60,"b) 10-60s",IF(P2<600,"c) 1-10min","d) >10min"))) -> d) >10min | R2: 1933.36 | S2: 1933.34 | T2: Initial stop loss | U2: =IF(R2="","",IF(F2="BUY",R2-S2,S2-R2)) -> 0.02 | V2: =IF(F2="BUY",S2-J2,J2-S2) -> -6.02 | W2: -48.16 | X2: =IFERROR(W2/N2,0) -> -1.0033333 | Y2: =IF(W2>0,"Win",IF(W2<0,"Loss","Flat")) -> Loss | Z2: =Summary!$C$5+SUM(W$2:W2) -> 4951.84 | AA2: =MAX(Summary!$C$5,Z2) -> 5000 | AB2: =AA2-Z2 -> 48.16 | AC2: =IFERROR(AB2/AA2,0) -> 0.009632 | AD2: BUY STOP at 1939.36 filled at 1939.360 ($0.00 better). SL $6.00 away = $48 risk. Price went against it; stopped at 1933.340 after 34m38s: -$48.16 (-1.00R).
A3: 2 | B3: 2022-04 | C3: 44652.732 | D3: Fri | E3: 17 | F3: SELL | G3: PDH_S | H3: 0.08 | I3: 1918.99 | J3: 1918.89 | K3: =IF(F3="BUY",J3-I3,I3-J3) -> 0.1 | L3: 1924.99 | M3: =ABS(I3-L3) -> 6 | N3: =M3*H3*Summary!$C$6 -> 48 | O3: 44652.739 | P3: =ROUND((O3-C3)*86400,0) -> 611 | Q3: =IF(P3<10,"a) <10s",IF(P3<60,"b) 10-60s",IF(P3<600,"c) 1-10min","d) >10min"))) -> d) >10min | R3: 1924.99 | S3: 1925.09 | T3: Initial stop loss | U3: =IF(R3="","",IF(F3="BUY",R3-S3,S3-R3)) -> 0.1 | V3: =IF(F3="BUY",S3-J3,J3-S3) -> -6.2 | W3: -49.6 | X3: =IFERROR(W3/N3,0) -> -1.0333333 | Y3: =IF(W3>0,"Win",IF(W3<0,"Loss","Flat")) -> Loss | Z3: =Summary!$C$5+SUM(W$2:W3) -> 4902.24 | AA3: =MAX(AA2,Z3) -> 5000 | AB3: =AA3-Z3 -> 97.76 | AC3: =IFERROR(AB3/AA3,0) -> 0.019552 | AD3: SELL STOP at 1918.99 filled at 1918.890 ($0.10 worse). SL $6.00 away = $48 risk. Price went against it; stopped at 1925.090 after 10m11s: -$49.60 (-1.03R).
A4: 3 | B4: 2022-04 | C4: 44655.301 | D4: Mon | E4: 7 | F4: SELL | G4: PDH_S | H4: 0.08 | I4: 1917.91 | J4: 1917.88 | K4: =IF(F4="BUY",J4-I4,I4-J4) -> 0.03 | L4: 1923.91 | M4: =ABS(I4-L4) -> 6 | N4: =M4*H4*Summary!$C$6 -> 48 | O4: 44655.312 | P4: =ROUND((O4-C4)*86400,0) -> 900 | Q4: =IF(P4<10,"a) <10s",IF(P4<60,"b) 10-60s",IF(P4<600,"c) 1-10min","d) >10min"))) -> d) >10min | R4: 1917.38 | S4: 1917.4 | T4: Breakeven/trailing stop | U4: =IF(R4="","",IF(F4="BUY",R4-S4,S4-R4)) -> 0.02 | V4: =IF(F4="BUY",S4-J4,J4-S4) -> 0.48 | W4: 3.84 | X4: =IFERROR(W4/N4,0) -> 0.08 | Y4: =IF(W4>0,"Win",IF(W4<0,"Loss","Flat")) -> Win | Z4: =Summary!$C$5+SUM(W$2:W4) -> 4906.08 | AA4: =MAX(AA3,Z4) -> 5000 | AB4: =AA4-Z4 -> 93.92 | AC4: =IFERROR(AB4/AA4,0) -> 0.018784 | AD4: SELL STOP at 1917.91 filled at 1917.880 ($0.03 worse). SL $6.00 away = $48 risk. Closed by the EA itself (account guard / blackout / instant close) at 1917.400 after 15m00s: +$3.84 (+0.08R).
A5: 4 | B5: 2022-04 | C5: 44655.39 | D5: Mon | E5: 9 | F5: BUY | G5: RANGE_B | H5: 0.08 | I5: 1921.11 | J5: 1921.11 | K5: =IF(F5="BUY",J5-I5,I5-J5) -> 0 | L5: 1915.11 | M5: =ABS(I5-L5) -> 6 | N5: =M5*H5*Summary!$C$6 -> 48 | O5: 44655.927 | P5: =ROUND((O5-C5)*86400,0) -> 46404 | Q5: =IF(P5<10,"a) <10s",IF(P5<60,"b) 10-60s",IF(P5<600,"c) 1-10min","d) >10min"))) -> d) >10min | S5: 1931.71 | T5: Closed by EA (no SL) | U5: =IF(R5="","",IF(F5="BUY",R5-S5,S5-R5)) | V5: =IF(F5="BUY",S5-J5,J5-S5) -> 10.6 | W5: 84.8 | X5: =IFERROR(W5/N5,0) -> 1.7666667 | Y5: =IF(W5>0,"Win",IF(W5<0,"Loss","Flat")) -> Win | Z5: =Summary!$C$5+SUM(W$2:W5) -> 4990.88 | AA5: =MAX(AA4,Z5) -> 5000 | AB5: =AA5-Z5 -> 9.12 | AC5: =IFERROR(AB5/AA5,0) -> 0.001824 | AD5: BUY STOP at 1921.11 filled at 1921.110 ($0.00 better). SL $6.00 away = $48 risk. Closed by the EA itself (account guard / blackout / instant close) at 1931.710 after 12h53m: +$84.80 (+1.77R).
A6: 5 | B6: 2022-04 | C6: 44656.457 | D6: Tue | E6: 10 | F6: SELL | G6: RANGE_S | H6: 0.08 | I6: 1926.41 | J6: 1926.41 | K6: =IF(F6="BUY",J6-I6,I6-J6) -> 0 | L6: 1932.41 | M6: =ABS(I6-L6) -> 6 | N6: =M6*H6*Summary!$C$6 -> 48 | O6: 44656.501 | P6: =ROUND((O6-C6)*86400,0) -> 3831 | Q6: =IF(P6<10,"a) <10s",IF(P6<60,"b) 10-60s",IF(P6<600,"c) 1-10min","d) >10min"))) -> d) >10min | R6: 1932.41 | S6: 1932.41 | T6: Initial stop loss | U6: =IF(R6="","",IF(F6="BUY",R6-S6,S6-R6)) -> 0 | V6: =IF(F6="BUY",S6-J6,J6-S6) -> -6 | W6: -48 | X6: =IFERROR(W6/N6,0) -> -1 | Y6: =IF(W6>0,"Win",IF(W6<0,"Loss","Flat")) -> Loss | Z6: =Summary!$C$5+SUM(W$2:W6) -> 4942.88 | AA6: =MAX(AA5,Z6) -> 5000 | AB6: =AA6-Z6 -> 57.12 | AC6: =IFERROR(AB6/AA6,0) -> 0.011424 | AD6: SELL STOP at 1926.41 filled at 1926.410 ($0.00 better). SL $6.00 away = $48 risk. Price went against it; stopped at 1932.410 after 1h03m: -$48.00 (-1.00R).
A7: 6 | B7: 2022-04 | C7: 44656.671 | D7: Tue | E7: 16 | F7: BUY | G7: PDH_B | H7: 0.08 | I7: 1936.88 | J7: 1936.88 | K7: =IF(F7="BUY",J7-I7,I7-J7) -> 0 | L7: 1930.88 | M7: =ABS(I7-L7) -> 6 | N7: =M7*H7*Summary!$C$6 -> 48 | O7: 44656.687 | P7: =ROUND((O7-C7)*86400,0) -> 1403 | Q7: =IF(P7<10,"a) <10s",IF(P7<60,"b) 10-60s",IF(P7<600,"c) 1-10min","d) >10min"))) -> d) >10min | R7: 1937.38 | S7: 1937.36 | T7: Breakeven/trailing stop | U7: =IF(R7="","",IF(F7="BUY",R7-S7,S7-R7)) -> 0.02 | V7: =IF(F7="BUY",S7-J7,J7-S7) -> 0.48 | W7: 3.84 | X7: =IFERROR(W7/N7,0) -> 0.08 | Y7: =IF(W7>0,"Win",IF(W7<0,"Loss","Flat")) -> Win | Z7: =Summary!$C$5+SUM(W$2:W7) -> 4946.72 | AA7: =MAX(AA6,Z7) -> 5000 | AB7: =AA7-Z7 -> 53.28 | AC7: =IFERROR(AB7/AA7,0) -> 0.010656 | AD7: BUY STOP at 1936.88 filled at 1936.880 ($0.00 better). SL $6.00 away = $48 risk. Closed by the EA itself (account guard / blackout / instant close) at 1937.360 after 23m23s: +$3.84 (+0.08R).
A8: 7 | B8: 2022-04 | C8: 44657.164 | D8: Wed | E8: 3 | F8: SELL | G8: PDH_S | H8: 0.08 | I8: 1917.84 | J8: 1917.58 | K8: =IF(F8="BUY",J8-I8,I8-J8) -> 0.26 | L8: 1923.84 | M8: =ABS(I8-L8) -> 6 | N8: =M8*H8*Summary!$C$6 -> 48 | O8: 44657.185 | P8: =ROUND((O8-C8)*86400,0) -> 1766 | Q8: =IF(P8<10,"a) <10s",IF(P8<60,"b) 10-60s",IF(P8<600,"c) 1-10min","d) >10min"))) -> d) >10min | R8: 1923.84 | S8: 1923.85 | T8: Initial stop loss | U8: =IF(R8="","",IF(F8="BUY",R8-S8,S8-R8)) -> 0.01 | V8: =IF(F8="BUY",S8-J8,J8-S8) -> -6.27 | W8: -50.16 | X8: =IFERROR(W8/N8,0) -> -1.045 | Y8: =IF(W8>0,"Win",IF(W8<0,"Loss","Flat")) -> Loss | Z8: =Summary!$C$5+SUM(W$2:W8) -> 4896.56 | AA8: =MAX(AA7,Z8) -> 5000 | AB8: =AA8-Z8 -> 103.44 | AC8: =IFERROR(AB8/AA8,0) -> 0.020688 | AD8: SELL STOP at 1917.84 filled at 1917.580 ($0.26 worse). SL $6.00 away = $48 risk. Price went against it; stopped at 1923.850 after 29m26s: -$50.16 (-1.04R).
A9: 8 | B9: 2022-04 | C9: 44657.376 | D9: Wed | E9: 9 | F9: SELL | G9: RANGE_S | H9: 0.08 | I9: 1920.41 | J9: 1920.41 | K9: =IF(F9="BUY",J9-I9,I9-J9) -> 0 | L9: 1926.41 | M9: =ABS(I9-L9) -> 6 | N9: =M9*H9*Summary!$C$6 -> 48 | O9: 44657.417 | P9: =ROUND((O9-C9)*86400,0) -> 3509 | Q9: =IF(P9<10,"a) <10s",IF(P9<60,"b) 10-60s",IF(P9<600,"c) 1-10min","d) >10min"))) -> d) >10min | R9: 1919.91 | S9: 1919.95 | T9: Breakeven/trailing stop | U9: =IF(R9="","",IF(F9="BUY",R9-S9,S9-R9)) -> 0.04 | V9: =IF(F9="BUY",S9-J9,J9-S9) -> 0.46 | W9: 3.68 | X9: =IFERROR(W9/N9,0) -> 0.076666667 | Y9: =IF(W9>0,"Win",IF(W9<0,"Loss","Flat")) -> Win | Z9: =Summary!$C$5+SUM(W$2:W9) -> 4900.24 | AA9: =MAX(AA8,Z9) -> 5000 | AB9: =AA9-Z9 -> 99.76 | AC9: =IFERROR(AB9/AA9,0) -> 0.019952 | AD9: SELL STOP at 1920.41 filled at 1920.410 ($0.00 better). SL $6.00 away = $48 risk. Closed by the EA itself (account guard / blackout / instant close) at 1919.950 after 58m29s: +$3.68 (+0.08R).
A10: 9 | B10: 2022-04 | C10: 44658.376 | D10: Thu | E10: 9 | F10: BUY | G10: RANGE_B | H10: 0.08 | I10: 1923.82 | J10: 1923.82 | K10: =IF(F10="BUY",J10-I10,I10-J10) -> 0 | L10: 1917.82 | M10: =ABS(I10-L10) -> 6 | N10: =M10*H10*Summary!$C$6 -> 48 | O10: 44658.445 | P10: =ROUND((O10-C10)*86400,0) -> 5989 | Q10: =IF(P10<10,"a) <10s",IF(P10<60,"b) 10-60s",IF(P10<600,"c) 1-10min","d) >10min"))) -> d) >10min | R10: 1924.32 | S10: 1924.22 | T10: Breakeven/trailing stop | U10: =IF(R10="","",IF(F10="BUY",R10-S10,S10-R10)) -> 0.1 | V10: =IF(F10="BUY",S10-J10,J10-S10) -> 0.4 | W10: 3.2 | X10: =IFERROR(W10/N10,0) -> 0.066666667 | Y10: =IF(W10>0,"Win",IF(W10<0,"Loss","Flat")) -> Win | Z10: =Summary!$C$5+SUM(W$2:W10) -> 4903.44 | AA10: =MAX(AA9,Z10) -> 5000 | AB10: =AA10-Z10 -> 96.56 | AC10: =IFERROR(AB10/AA10,0) -> 0.019312 | AD10: BUY STOP at 1923.82 filled at 1923.820 ($0.00 better). SL $6.00 away = $48 risk. Closed by the EA itself (account guard / blackout / instant close) at 1924.220 after 1h39m: +$3.20 (+0.07R).
A11: 10 | B11: 2022-04 | C11: 44658.631 | D11: Thu | E11: 15 | F11: BUY | G11: PDH_B | H11: 0.08 | I11: 1933.35 | J11: 1933.91 | K11: =IF(F11="BUY",J11-I11,I11-J11) -> 0.56 | L11: 1927.35 | M11: =ABS(I11-L11) -> 6 | N11: =M11*H11*Summary!$C$6 -> 48 | O11: 44658.646 | P11: =ROUND((O11-C11)*86400,0) -> 1325 | Q11: =IF(P11<10,"a) <10s",IF(P11<60,"b) 10-60s",IF(P11<600,"c) 1-10min","d) >10min"))) -> d) >10min | R11: 1927.35 | S11: 1927.15 | T11: Initial stop loss | U11: =IF(R11="","",IF(F11="BUY",R11-S11,S11-R11)) -> 0.2 | V11: =IF(F11="BUY",S11-J11,J11-S11) -> -6.76 | W11: -54.08 | X11: =IFERROR(W11/N11,0) -> -1.1266667 | Y11: =IF(W11>0,"Win",IF(W11<0,"Loss","Flat")) -> Loss | Z11: =Summary!$C$5+SUM(W$2:W11) -> 4849.36 | AA11: =MAX(AA10,Z11) -> 5000 | AB11: =AA11-Z11 -> 150.64 | AC11: =IFERROR(AB11/AA11,0) -> 0.030128 | AD11: BUY STOP at 1933.35 filled at 1933.910 ($0.56 worse). SL $6.00 away = $48 risk. Price went against it; stopped at 1927.150 after 22m05s: -$54.08 (-1.13R).
A12: 11 | B12: 2022-04 | C12: 44659.377 | D12: Fri | E12: 9 | F12: BUY | G12: RANGE_B | H12: 0.08 | I12: 1932.27 | J12: 1932.28 | K12: =IF(F12="BUY",J12-I12,I12-J12) -> 0.01 | L12: 1926.27 | M12: =ABS(I12-L12) -> 6 | N12: =M12*H12*Summary!$C$6 -> 48 | O12: 44659.586 | P12: =ROUND((O12-C12)*86400,0) -> 18063 | Q12: =IF(P12<10,"a) <10s",IF(P12<60,"b) 10-60s",IF(P12<600,"c) 1-10min","d) >10min"))) -> d) >10min | R12: 1932.78 | S12: 1932.77 | T12: Breakeven/trailing stop | U12: =IF(R12="","",IF(F12="BUY",R12-S12,S12-R12)) -> 0.01 | V12: =IF(F12="BUY",S12-J12,J12-S12) -> 0.49 | W12: 3.92 | X12: =IFERROR(W12/N12,0) -> 0.081666667 | Y12: =IF(W12>0,"Win",IF(W12<0,"Loss","Flat")) -> Win | Z12: =Summary!$C$5+SUM(W$2:W12) -> 4853.28 | AA12: =MAX(AA11,Z12) -> 5000 | AB12: =AA12-Z12 -> 146.72 | AC12: =IFERROR(AB12/AA12,0) -> 0.029344 | AD12: BUY STOP at 1932.27 filled at 1932.280 ($0.01 worse). SL $6.00 away = $48 risk. Closed by the EA itself (account guard / blackout / instant close) at 1932.770 after 5h01m: +$3.92 (+0.08R).
A13: 12 | B13: 2022-04 | C13: 44659.635 | D13: Fri | E13: 15 | F13: BUY | G13: PDH_B | H13: 0.08 | I13: 1937.71 | J13: 1938.01 | K13: =IF(F13="BUY",J13-I13,I13-J13) -> 0.3 | L13: 1931.71 | M13: =ABS(I13-L13) -> 6 | N13: =M13*H13*Summary!$C$6 -> 48 | O13: 44659.649 | P13: =ROUND((O13-C13)*86400,0) -> 1223 | Q13: =IF(P13<10,"a) <10s",IF(P13<60,"b) 10-60s",IF(P13<600,"c) 1-10min","d) >10min"))) -> d) >10min | R13: 1931.71 | S13: 1931.63 | T13: Initial stop loss | U13: =IF(R13="","",IF(F13="BUY",R13-S13,S13-R13)) -> 0.08 | V13: =IF(F13="BUY",S13-J13,J13-S13) -> -6.38 | W13: -51.04 | X13: =IFERROR(W13/N13,0) -> -1.0633333 | Y13: =IF(W13>0,"Win",IF(W13<0,"Loss","Flat")) -> Loss | Z13: =Summary!$C$5+SUM(W$2:W13) -> 4802.24 | AA13: =MAX(AA12,Z13) -> 5000 | AB13: =AA13-Z13 -> 197.76 | AC13: =IFERROR(AB13/AA13,0) -> 0.039552 | AD13: BUY STOP at 1937.71 filled at 1938.010 ($0.30 worse). SL $6.00 away = $48 risk. Price went against it; stopped at 1931.630 after 20m23s: -$51.04 (-1.06R).
A14: 13 | B14: 2022-04 | C14: 44663.423 | D14: Tue | E14: 10 | F14: SELL | G14: RANGE_S | H14: 0.08 | I14: 1955.61 | J14: 1955.61 | K14: =IF(F14="BUY",J14-I14,I14-J14) -> 0 | L14: 1961.61 | M14: =ABS(I14-L14) -> 6 | N14: =M14*H14*Summary!$C$6 -> 48 | O14: 44663.462 | P14: =ROUND((O14-C14)*86400,0) -> 3426 | Q14: =IF(P14<10,"a) <10s",IF(P14<60,"b) 10-60s",IF(P14<600,"c) 1-10min","d) >10min"))) -> d) >10min | R14: 1955.11 | S14: 1955.11 | T14: Breakeven/trailing stop | U14: =IF(R14="","",IF(F14="BUY",R14-S14,S14-R14)) -> 0 | V14: =IF(F14="BUY",S14-J14,J14-S14) -> 0.5 | W14: 4 | X14: =IFERROR(W14/N14,0) -> 0.083333333 | Y14: =IF(W14>0,"Win",IF(W14<0,"Loss","Flat")) -> Win | Z14: =Summary!$C$5+SUM(W$2:W14) -> 4806.24 | AA14: =MAX(AA13,Z14) -> 5000 | AB14: =AA14-Z14 -> 193.76 | AC14: =IFERROR(AB14/AA14,0) -> 0.038752 | AD14: SELL STOP at 1955.61 filled at 1955.610 ($0.00 better). SL $6.00 away = $48 risk. Closed by the EA itself (account guard / blackout / instant close) at 1955.110 after 57m06s: +$4.00 (+0.08R).
A15: 14 | B15: 2022-04 | C15: 44663.663 | D15: Tue | E15: 15 | F15: BUY | G15: PDH_B | H15: 0.08 | I15: 1969.56 | J15: 1969.72 | K15: =IF(F15="BUY",J15-I15,I15-J15) -> 0.16 | L15: 1963.56 | M15: =ABS(I15-L15) -> 6 | N15: =M15*H15*Summary!$C$6 -> 48 | O15: 44663.664 | P15: =ROUND((O15-C15)*86400,0) -> 89 | Q15: =IF(P15<10,"a) <10s",IF(P15<60,"b) 10-60s",IF(P15<600,"c) 1-10min","d) >10min"))) -> c) 1-10min | R15: 1970.22 | S15: 1970.2 | T15: Breakeven/trailing stop | U15: =IF(R15="","",IF(F15="BUY",R15-S15,S15-R15)) -> 0.02 | V15: =IF(F15="BUY",S15-J15,J15-S15) -> 0.48 | W15: 3.84 | X15: =IFERROR(W15/N15,0) -> 0.08 | Y15: =IF(W15>0,"Win",IF(W15<0,"Loss","Flat")) -> Win | Z15: =Summary!$C$5+SUM(W$2:W15) -> 4810.08 | AA15: =MAX(AA14,Z15) -> 5000 | AB15: =AA15-Z15 -> 189.92 | AC15: =IFERROR(AB15/AA15,0) -> 0.037984 | AD15: BUY STOP at 1969.56 filled at 1969.720 ($0.16 worse). SL $6.00 away = $48 risk. Closed by the EA itself (account guard / blackout / instant close) at 1970.200 after 1m29s: +$3.84 (+0.08R).
A16: 15 | B16: 2022-04 | C16: 44664.394 | D16: Wed | E16: 9 | F16: SELL | G16: RANGE_S | H16: 0.08 | I16: 1967.61 | J16: 1967.61 | K16: =IF(F16="BUY",J16-I16,I16-J16) -> 0 | L16: 1973.61 | M16: =ABS(I16-L16) -> 6 | N16: =M16*H16*Summary!$C$6 -> 48 | O16: 44664.47 | P16: =ROUND((O16-C16)*86400,0) -> 6592 | Q16: =IF(P16<10,"a) <10s",IF(P16<60,"b) 10-60s",IF(P16<600,"c) 1-10min","d) >10min"))) -> d) >10min | R16: 1973.61 | S16: 1973.62 | T16: Initial stop loss | U16: =IF(R16="","",IF(F16="BUY",R16-S16,S16-R16)) -> 0.01 | V16: =IF(F16="BUY",S16-J16,J16-S16) -> -6.01 | W16: -48.08 | X16: =IFERROR(W16/N16,0) -> -1.0016667 | Y16: =IF(W16>0,"Win",IF(W16<0,"Loss","Flat")) -> Loss | Z16: =Summary!$C$5+SUM(W$2:W16) -> 4762 | AA16: =MAX(AA15,Z16) -> 5000 | AB16: =AA16-Z16 -> 238 | AC16: =IFERROR(AB16/AA16,0) -> 0.0476 | AD16: SELL STOP at 1967.61 filled at 1967.610 ($0.00 better). SL $6.00 away = $48 risk. Price went against it; stopped at 1973.620 after 1h49m: -$48.08 (-1.00R).
A17: 16 | B17: 2022-04 | C17: 44664.532 | D17: Wed | E17: 12 | F17: BUY | G17: PDH_B | H17: 0.07 | I17: 1978.51 | J17: 1978.86 | K17: =IF(F17="BUY",J17-I17,I17-J17) -> 0.35 | L17: 1972.51 | M17: =ABS(I17-L17) -> 6 | N17: =M17*H17*Summary!$C$6 -> 42 | O17: 44664.643 | P17: =ROUND((O17-C17)*86400,0) -> 9594 | Q17: =IF(P17<10,"a) <10s",IF(P17<60,"b) 10-60s",IF(P17<600,"c) 1-10min","d) >10min"))) -> d) >10min | R17: 1972.51 | S17: 1972.41 | T17: Initial stop loss | U17: =IF(R17="","",IF(F17="BUY",R17-S17,S17-R17)) -> 0.1 | V17: =IF(F17="BUY",S17-J17,J17-S17) -> -6.45 | W17: -45.15 | X17: =IFERROR(W17/N17,0) -> -1.075 | Y17: =IF(W17>0,"Win",IF(W17<0,"Loss","Flat")) -> Loss | Z17: =Summary!$C$5+SUM(W$2:W17) -> 4716.85 | AA17: =MAX(AA16,Z17) -> 5000 | AB17: =AA17-Z17 -> 283.15 | AC17: =IFERROR(AB17/AA17,0) -> 0.05663 | AD17: BUY STOP at 1978.51 filled at 1978.860 ($0.35 worse). SL $6.00 away = $42 risk. Price went against it; stopped at 1972.410 after 2h39m: -$45.15 (-1.07R).
... A21: 20 | B21: 2022-04 | C21: 44670.434 | D21: Tue | E21: 10 | F21: BUY | G21: RANGE_B | H21: 0.07 | I21: 1978.65 | J21: 1978.73 | K21: =IF(F21="BUY",J21-I21,I21-J21) -> 0.08 | L21: 1972.65 | M21: =ABS(I21-L21) -> 6 | N21: =M21*H21*Summary!$C$6 -> 42 | O21: 44670.485 | P21: =ROUND((O21-C21)*86400,0) -> 4449 | Q21: =IF(P21<10,"a) <10s",IF(P21<60,"b) 10-60s",IF(P21<600,"c) 1-10min","d) >10min"))) -> d) >10min | R21: 1979.23 | S21: 1979.21 | T21: Breakeven/trailing stop | U21: =IF(R21="","",IF(F21="BUY",R21-S21,S21-R21)) -> 0.02 | V21: =IF(F21="BUY",S21-J21,J21-S21) -> 0.48 | W21: 3.36 | X21: =IFERROR(W21/N21,0) -> 0.08 | Y21: =IF(W21>0,"Win",IF(W21<0,"Loss","Flat")) -> Win | Z21: =Summary!$C$5+SUM(W$2:W21) -> 4637.68 | AA21: =MAX(AA20,Z21) -> 5000 | AB21: =AA21-Z21 -> 362.32 | AC21: =IFERROR(AB21/AA21,0) -> 0.072464 | AD21: BUY STOP at 1978.65 filled at 1978.730 ($0.08 worse). SL $6.00 away = $42 risk. Closed by the EA itself (account guard / blackout / instant close) at 1979.210 after 1h14m: +$3.36 (+0.08R).
A22: 21 | B22: 2022-04 | C22: 44670.655 | D22: Tue | E22: 15 | F22: SELL | G22: PDH_S | H22: 0.07 | I22: 1970.84 | J22: 1970.79 | K22: =IF(F22="BUY",J22-I22,I22-J22) -> 0.05 | L22: 1976.84 | M22: =ABS(I22-L22) -> 6 | N22: =M22*H22*Summary!$C$6 -> 42 | O22: 44670.927 | P22: =ROUND((O22-C22)*86400,0) -> 23519 | Q22: =IF(P22<10,"a) <10s",IF(P22<60,"b) 10-60s",IF(P22<600,"c) 1-10min","d) >10min"))) -> d) >10min | S22: 1950.18 | T22: Closed by EA (no SL) | U22: =IF(R22="","",IF(F22="BUY",R22-S22,S22-R22)) | V22: =IF(F22="BUY",S22-J22,J22-S22) -> 20.61 | W22: 144.27 | X22: =IFERROR(W22/N22,0) -> 3.435 | Y22: =IF(W22>0,"Win",IF(W22<0,"Loss","Flat")) -> Win | Z22: =Summary!$C$5+SUM(W$2:W22) -> 4781.95 | AA22: =MAX(AA21,Z22) -> 5000 | AB22: =AA22-Z22 -> 218.05 | AC22: =IFERROR(AB22/AA22,0) -> 0.04361 | AD22: SELL STOP at 1970.84 filled at 1970.790 ($0.05 worse). SL $6.00 away = $42 risk. Closed by the EA itself (account guard / blackout / instant close) at 1950.180 after 6h31m: +$144.27 (+3.43R).
A23: 22 | B23: 2022-04 | C23: 44671.183 | D23: Wed | E23: 4 | F23: SELL | G23: PDH_S | H23: 0.07 | I23: 1943.59 | J23: 1943.36 | K23: =IF(F23="BUY",J23-I23,I23-J23) -> 0.23 | L23: 1949.59 | M23: =ABS(I23-L23) -> 6 | N23: =M23*H23*Summary!$C$6 -> 42 | O23: 44671.295 | P23: =ROUND((O23-C23)*86400,0) -> 9733 | Q23: =IF(P23<10,"a) <10s",IF(P23<60,"b) 10-60s",IF(P23<600,"c) 1-10min","d) >10min"))) -> d) >10min | R23: 1942.86 | S23: 1942.89 | T23: Breakeven/trailing stop | U23: =IF(R23="","",IF(F23="BUY",R23-S23,S23-R23)) -> 0.03 | V23: =IF(F23="BUY",S23-J23,J23-S23) -> 0.47 | W23: 3.29 | X23: =IFERROR(W23/N23,0) -> 0.078333333 | Y23: =IF(W23>0,"Win",IF(W23<0,"Loss","Flat")) -> Win | Z23: =Summary!$C$5+SUM(W$2:W23) -> 4785.24 | AA23: =MAX(AA22,Z23) -> 5000 | AB23: =AA23-Z23 -> 214.76 | AC23: =IFERROR(AB23/AA23,0) -> 0.042952 | AD23: SELL STOP at 1943.59 filled at 1943.360 ($0.23 worse). SL $6.00 away = $42 risk. Closed by the EA itself (account guard / blackout / instant close) at 1942.890 after 2h42m: +$3.29 (+0.08R).
A24: 23 | B24: 2022-04 | C24: 44671.379 | D24: Wed | E24: 9 | F24: SELL | G24: RANGE_S | H24: 0.07 | I24: 1940.42 | J24: 1940.41 | K24: =IF(F24="BUY",J24-I24,I24-J24) -> 0.01 | L24: 1946.42 | M24: =ABS(I24-L24) -> 6 | N24: =M24*H24*Summary!$C$6 -> 42 | O24: 44671.494 | P24: =ROUND((O24-C24)*86400,0) -> 9959 | Q24: =IF(P24<10,"a) <10s",IF(P24<60,"b) 10-60s",IF(P24<600,"c) 1-10min","d) >10min"))) -> d) >10min | R24: 1946.42 | S24: 1946.45 | T24: Initial stop loss | U24: =IF(R24="","",IF(F24="BUY",R24-S24,S24-R24)) -> 0.03 | V24: =IF(F24="BUY",S24-J24,J24-S24) -> -6.04 | W24: -42.28 | X24: =IFERROR(W24/N24,0) -> -1.0066667 | Y24: =IF(W24>0,"Win",IF(W24<0,"Loss","Flat")) -> Loss | Z24: =Summary!$C$5+SUM(W$2:W24) -> 4742.96 | AA24: =MAX(AA23,Z24) -> 5000 | AB24: =AA24-Z24 -> 257.04 | AC24: =IFERROR(AB24/AA24,0) -> 0.051408 | AD24: SELL STOP at 1940.42 filled at 1940.410 ($0.01 worse). SL $6.00 away = $42 risk. Price went against it; stopped at 1946.450 after 2h45m: -$42.28 (-1.01R).
A25: 24 | B25: 2022-04 | C25: 44672.375 | D25: Thu | E25: 9 | F25: BUY | G25: RANGE_B | H25: 0.07 | I25: 1953.87 | J25: 1953.95 | K25: =IF(F25="BUY",J25-I25,I25-J25) -> 0.08 | L25: 1947.87 | M25: =ABS(I25-L25) -> 6 | N25: =M25*H25*Summary!$C$6 -> 42 | O25: 44672.462 | P25: =ROUND((O25-C25)*86400,0) -> 7516 | Q25: =IF(P25<10,"a) <10s",IF(P25<60,"b) 10-60s",IF(P25<600,"c) 1-10min","d) >10min"))) -> d) >10min | R25: 1947.87 | S25: 1947.87 | T25: Initial stop loss | U25: =IF(R25="","",IF(F25="BUY",R25-S25,S25-R25)) -> 0 | V25: =IF(F25="BUY",S25-J25,J25-S25) -> -6.08 | W25: -42.56 | X25: =IFERROR(W25/N25,0) -> -1.0133333 | Y25: =IF(W25>0,"Win",IF(W25<0,"Loss","Flat")) -> Loss | Z25: =Summary!$C$5+SUM(W$2:W25) -> 4700.4 | AA25: =MAX(AA24,Z25) -> 5000 | AB25: =AA25-Z25 -> 299.6 | AC25: =IFERROR(AB25/AA25,0) -> 0.05992 | AD25: BUY STOP at 1953.87 filled at 1953.950 ($0.08 worse). SL $6.00 away = $42 risk. Price went against it; stopped at 1947.870 after 2h05m: -$42.56 (-1.01R).
A26: 25 | B26: 2022-04 | C26: 44672.612 | D26: Thu | E26: 14 | F26: SELL | G26: PDH_S | H26: 0.07 | I26: 1939.16 | J26: 1939.16 | K26: =IF(F26="BUY",J26-I26,I26-J26) -> 0 | L26: 1945.16 | M26: =ABS(I26-L26) -> 6 | N26: =M26*H26*Summary!$C$6 -> 42 | O26: 44672.614 | P26: =ROUND((O26-C26)*86400,0) -> 101 | Q26: =IF(P26<10,"a) <10s",IF(P26<60,"b) 10-60s",IF(P26<600,"c) 1-10min","d) >10min"))) -> c) 1-10min | R26: 1938.66 | S26: 1938.74 | T26: Breakeven/trailing stop | U26: =IF(R26="","",IF(F26="BUY",R26-S26,S26-R26)) -> 0.08 | V26: =IF(F26="BUY",S26-J26,J26-S26) -> 0.42 | W26: 2.94 | X26: =IFERROR(W26/N26,0) -> 0.07 | Y26: =IF(W26>0,"Win",IF(W26<0,"Loss","Flat")) -> Win | Z26: =Summary!$C$5+SUM(W$2:W26) -> 4703.34 | AA26: =MAX(AA25,Z26) -> 5000 | AB26: =AA26-Z26 -> 296.66 | AC26: =IFERROR(AB26/AA26,0) -> 0.059332 | AD26: SELL STOP at 1939.16 filled at 1939.160 ($0.00 better). SL $6.00 away = $42 risk. Closed by the EA itself (account guard / blackout / instant close) at 1938.740 after 1m41s: +$2.94 (+0.07R).
A27: 26 | B27: 2022-04 | C27: 44673.459 | D27: Fri | E27: 11 | F27: SELL | G27: RANGE_S | H27: 0.07 | I27: 1949.57 | J27: 1949.56 | K27: =IF(F27="BUY",J27-I27,I27-J27) -> 0.01 | L27: 1955.57 | M27: =ABS(I27-L27) -> 6 | N27: =M27*H27*Summary!$C$6 -> 42 | O27: 44673.927 | P27: =ROUND((O27-C27)*86400,0) -> 40420 | Q27: =IF(P27<10,"a) <10s",IF(P27<60,"b) 10-60s",IF(P27<600,"c) 1-10min","d) >10min"))) -> d) >10min | S27: 1932.47 | T27: Closed by EA (no SL) | U27: =IF(R27="","",IF(F27="BUY",R27-S27,S27-R27)) | V27: =IF(F27="BUY",S27-J27,J27-S27) -> 17.09 | W27: 119.63 | X27: =IFERROR(W27/N27,0) -> 2.8483333 | Y27: =IF(W27>0,"Win",IF(W27<0,"Loss","Flat")) -> Win | Z27: =Summary!$C$5+SUM(W$2:W27) -> 4822.97 | AA27: =MAX(AA26,Z27) -> 5000 | AB27: =AA27-Z27 -> 177.03 | AC27: =IFERROR(AB27/AA27,0) -> 0.035406 | AD27: SELL STOP at 1949.57 filled at 1949.560 ($0.01 worse). SL $6.00 away = $42 risk. Closed by the EA itself (account guard / blackout / instant close) at 1932.470 after 11h13m: +$119.63 (+2.85R).
A28: 27 | B28: 2022-04 | C28: 44676.159 | D28: Mon | E28: 3 | F28: SELL | G28: PDH_S | H28: 0.08 | I28: 1926.46 | J28: 1926.45 | K28: =IF(F28="BUY",J28-I28,I28-J28) -> 0.01 | L28: 1932.46 | M28: =ABS(I28-L28) -> 6 | N28: =M28*H28*Summary!$C$6 -> 48 | O28: 44676.238 | P28: =ROUND((O28-C28)*86400,0) -> 6804 | Q28: =IF(P28<10,"a) <10s",IF(P28<60,"b) 10-60s",IF(P28<600,"c) 1-10min","d) >10min"))) -> d) >10min | R28: 1925.95 | S28: 1926.06 | T28: Breakeven/trailing stop | U28: =IF(R28="","",IF(F28="BUY",R28-S28,S28-R28)) -> 0.11 | V28: =IF(F28="BUY",S28-J28,J28-S28) -> 0.39 | W28: 3.12 | X28: =IFERROR(W28/N28,0) -> 0.065 | Y28: =IF(W28>0,"Win",IF(W28<0,"Loss","Flat")) -> Win | Z28: =Summary!$C$5+SUM(W$2:W28) -> 4826.09 | AA28: =MAX(AA27,Z28) -> 5000 | AB28: =AA28-Z28 -> 173.91 | AC28: =IFERROR(AB28/AA28,0) -> 0.034782 | AD28: SELL STOP at 1926.46 filled at 1926.450 ($0.01 worse). SL $6.00 away = $48 risk. Closed by the EA itself (account guard / blackout / instant close) at 1926.060 after 1h53m: +$3.12 (+0.07R).
A29: 28 | B29: 2022-04 | C29: 44676.398 | D29: Mon | E29: 9 | F29: SELL | G29: RANGE_S | H29: 0.08 | I29: 1913.14 | J29: 1913.11 | K29: =IF(F29="BUY",J29-I29,I29-J29) -> 0.03 | L29: 1919.14 | M29: =ABS(I29-L29) -> 6 | N29: =M29*H29*Summary!$C$6 -> 48 | O29: 44676.423 | P29: =ROUND((O29-C29)*86400,0) -> 2144 | Q29: =IF(P29<10,"a) <10s",IF(P29<60,"b) 10-60s",IF(P29<600,"c) 1-10min","d) >10min"))) -> d) >10min | R29: 1919.14 | S29: 1919.22 | T29: Initial stop loss | U29: =IF(R29="","",IF(F29="BUY",R29-S29,S29-R29)) -> 0.08 | V29: =IF(F29="BUY",S29-J29,J29-S29) -> -6.11 | W29: -48.88 | X29: =IFERROR(W29/N29,0) -> -1.0183333 | Y29: =IF(W29>0,"Win",IF(W29<0,"Loss","Flat")) -> Loss | Z29: =Summary!$C$5+SUM(W$2:W29) -> 4777.21 | AA29: =MAX(AA28,Z29) -> 5000 | AB29: =AA29-Z29 -> 222.79 | AC29: =IFERROR(AB29/AA29,0) -> 0.044558 | AD29: SELL STOP at 1913.14 filled at 1913.110 ($0.03 worse). SL $6.00 away = $48 risk. Price went against it; stopped at 1919.220 after 35m44s: -$48.88 (-1.02R).
A30: 29 | B30: 2022-04 | C30: 44677.399 | D30: Tue | E30: 9 | F30: SELL | G30: RANGE_S | H30: 0.07 | I30: 1901.38 | J30: 1901.36 | K30: =IF(F30="BUY",J30-I30,I30-J30) -> 0.02 | L30: 1907.38 | M30: =ABS(I30-L30) -> 6 | N30: =M30*H30*Summary!$C$6 -> 42 | O30: 44677.466 | P30: =ROUND((O30-C30)*86400,0) -> 5751 | Q30: =IF(P30<10,"a) <10s",IF(P30<60,"b) 10-60s",IF(P30<600,"c) 1-10min","d) >10min"))) -> d) >10min | R30: 1900.86 | S30: 1900.97 | T30: Breakeven/trailing stop | U30: =IF(R30="","",IF(F30="BUY",R30-S30,S30-R30)) -> 0.11 | V30: =IF(F30="BUY",S30-J30,J30-S30) -> 0.39 | W30: 2.73 | X30: =IFERROR(W30/N30,0) -> 0.065 | Y30: =IF(W30>0,"Win",IF(W30<0,"Loss","Flat")) -> Win | Z30: =Summary!$C$5+SUM(W$2:W30) -> 4779.94 | AA30: =MAX(AA29,Z30) -> 5000 | AB30: =AA30-Z30 -> 220.06 | AC30: =IFERROR(AB30/AA30,0) -> 0.044012 | AD30: SELL STOP at 1901.38 filled at 1901.360 ($0.02 worse). SL $6.00 away = $42 risk. Closed by the EA itself (account guard / blackout / instant close) at 1900.970 after 1h35m: +$2.73 (+0.06R).
A31: 30 | B31: 2022-04 | C31: 44678.395 | D31: Wed | E31: 9 | F31: BUY | G31: RANGE_B | H31: 0.07 | I31: 1900.66 | J31: 1900.74 | K31: =IF(F31="BUY",J31-I31,I31-J31) -> 0.08 | L31: 1894.66 | M31: =ABS(I31-L31) -> 6 | N31: =M31*H31*Summary!$C$6 -> 42 | O31: 44678.442 | P31: =ROUND((O31-C31)*86400,0) -> 4093 | Q31: =IF(P31<10,"a) <10s",IF(P31<60,"b) 10-60s",IF(P31<600,"c) 1-10min","d) >10min"))) -> d) >10min | R31: 1901.24 | S31: 1901.22 | T31: Breakeven/trailing stop | U31: =IF(R31="","",IF(F31="BUY",R31-S31,S31-R31)) -> 0.02 | V31: =IF(F31="BUY",S31-J31,J31-S31) -> 0.48 | W31: 3.36 | X31: =IFERROR(W31/N31,0) -> 0.08 | Y31: =IF(W31>0,"Win",IF(W31<0,"Loss","Flat")) -> Win | Z31: =Summary!$C$5+SUM(W$2:W31) -> 4783.3 | AA31: =MAX(AA30,Z31) -> 5000 | AB31: =AA31-Z31 -> 216.7 | AC31: =IFERROR(AB31/AA31,0) -> 0.04334 | AD31: BUY STOP at 1900.66 filled at 1900.740 ($0.08 worse). SL $6.00 away = $42 risk. Closed by the EA itself (account guard / blackout / instant close) at 1901.220 after 1h08m: +$3.36 (+0.08R).
