Workbook

Sheet Read Me
A1: How to read this workbook
A3: Summary | B3: Key numbers next to the MT5 report's own figures, verdicts, findings, balance and drawdown charts.
A4: Yearly / Monthly / Weekly / Daily | B4: One row per period: trades, wins, win rate, net, profit factor, best/worst trade, total R, start/end balance and return. Daily flags days that hit the daily loss limit.
A5: Calendar | B5: Year x month grid of net profit (colour scale), trades per month and win rate per month.
A6: Trades | B6: Every trade on one row: entry deal matched to its exit, SL/TP, planned risk, exit reason, R, hold time, balance and drawdown. Use the filter arrows in the header row.
A7: Breakdown | B7: Results split by side, setup, exit reason, weekday, entry hour, hold time, SL size, year, and the R distribution.
A8: Drawdowns & Streaks | B8: The 10 deepest drawdown periods with dates and recovery time, longest win/loss streaks.
A9: MT5 Report / Settings | B9: The tester's original statistics and the EA inputs used.
A11: Dates | B11: Profit is booked on the trade's CLOSE date/time (broker server time).
A12: R multiple | B12: Net profit / planned risk. Planned risk = SL distance x lots x $ per point per lot (Summary C6).
A13: Win / Loss | B13: Breakeven stops that close a few dollars negative (slippage/commission) count as losses, as in MT5.
A14: Colours | B14: Blue = data from the MT5 report or inputs you may change. Black = formulas. Yellow = inputs.
A15: Source | B15: MT5 Strategy Tester report: Pdh pdl m1 atr on NDX100.m_S0, 883 trades. Net profit here matches the report's Total Net Profit (17717.69).

Sheet Summary
B1: Backtest analysis
B2: Pdh pdl m1 atr | NDX100.m_S0 | M1 (2023.04.01 - 2026.10.01) | 100% real ticks
B3: Blue cells are inputs: change them and every sheet recalculates.
B5: Starting balance | C5: 100000 | F5: From the report (Initial Deposit).
B6: $ per 1.00 point per 1.00 lot | C6: 20 | F6: Measured from the trades (profit / points / lots, median). NDX100.m_S0: 1 lot moving 1 point = $20.
B7: Daily loss limit (prop rule) | C7: 0.025 | F7: Used for the breach checks on Daily. Matches the EA input DailyLossPct when present.
B8: Max drawdown limit (prop rule) | C8: 0.1 | F8: Typical prop-firm overall limit.
B10: Metric | C10: Value | D10: MT5 report | E10: Verdict | F10: What it means
B11: RESULT
B12: Net profit | C12: =SUM(Trades!$X$2:$X$884) -> 17717.69 | D12: 17717.69 | E12: =IF(C12>0,"Profitable","Losing") -> Profitable | F12: Total money made over the whole test, after commission and swap.
B13: Final balance | C13: =C5+C12 -> 117717.69
B14: Return on starting balance | C14: =IFERROR(C12/C5,0) -> 0.1771769
B15: Gross profit | C15: =SUMIF(Trades!$X$2:$X$884,">0") -> 64334.51 | D15: 64334.51 | F15: Sum of all winning trades.
B16: Gross loss | C16: =SUMIF(Trades!$X$2:$X$884,"<0") -> -46616.82 | D16: -46616.82 | F16: Sum of all losing trades.
B17: Profit factor | C17: =IFERROR(C15/-C16,0) -> 1.3800708 | D17: 1.380071 | E17: =IF(C17>=1.5,"Strong",IF(C17>=1.2,"Good",IF(C17>=1,"Weak","Losing"))) -> Good | F17: Gross profit / gross loss. 1.2+ is decent for an intraday system, 1.5+ strong.
B18: Expectancy per trade $ | C18: =IFERROR(C12/C20,0) -> 20.065334 | D18: 20.065334 | F18: What one trade earns on average.
B19: TRADES
B20: Total trades | C20: =COUNT(Trades!$X$2:$X$884) -> 883 | D20: 883
B21: Wins | C21: =COUNTIF(Trades!$Z$2:$Z$884,"Win") -> 282 | D21: 290 (32.84%)
B22: Losses | C22: =COUNTIF(Trades!$Z$2:$Z$884,"Loss") -> 593 | D22: 593 (67.16%) | F22: Includes breakeven stops that lost a little to slippage.
B23: Win rate | C23: =IFERROR(C21/C20,0) -> 0.3193658
B24: Average win | C24: =IFERROR(AVERAGEIF(Trades!$X$2:$X$884,">0"),0) -> 228.13656 | D24: 221.84314
B25: Average loss | C25: =IFERROR(AVERAGEIF(Trades!$X$2:$X$884,"<0"),0) -> -78.611838 | D25: -78.611838
B26: Win/loss size ratio | C26: =IFERROR(C24/-C25,0) -> 2.9020637 | F26: Average win / average loss.
B27: Break-even win rate needed | C27: =IFERROR(-C25/(C24-C25),0) -> 0.25627465 | E27: =IF(C23>C27,"Above break-even","Below break-even") -> Above break-even | F27: Win rate needed to break even with these win/loss sizes.
B28: Largest win | C28: =MAX(Trades!$X$2:$X$884) -> 1033.59 | D28: 1033.59
B29: Largest loss | C29: =MIN(Trades!$X$2:$X$884) -> -568.08 | D29: -568.08
B30: Long trades / net | C30: =COUNTIF(Trades!$J$2:$J$884,"BUY") -> 508 | D30: 508 (35.24%) | E30: =SUMIF(Trades!$J$2:$J$884,"BUY",Trades!$X$2:$X$884) -> 9002.57 | F30: Verdict column = net $ of longs.
B31: Short trades / net | C31: =COUNTIF(Trades!$J$2:$J$884,"SELL") -> 375 | D31: 375 (29.60%) | E31: =SUMIF(Trades!$J$2:$J$884,"SELL",Trades!$X$2:$X$884) -> 8715.12 | F31: Verdict column = net $ of shorts.
B32: RISK (R multiples)
B33: Average planned risk per trade $ | C33: =AVERAGE(Trades!$R$2:$R$884) -> 114.90994 | F33: SL distance x lots x $ per point.
B34: Average planned risk % of balance | C34: =IFERROR(AVERAGE(Trades!$R$2:$R$884)/AVERAGE(Trades!$AD$2:$AD$884),0) -> 0.0010574461 | F34: Compare with the EA's RiskPercent.
B35: Average SL distance (points) | C35: =AVERAGE(Trades!$P$2:$P$884) -> 25.906376
B36: Average R per trade | C36: =AVERAGE(Trades!$Y$2:$Y$884) -> 0.20007864 | E36: =IF(C36>0,"Positive edge","No edge") -> Positive edge | F36: Expectancy in units of risk.
B37: Total R | C37: =SUM(Trades!$Y$2:$Y$884) -> 176.66944
B38: Average R of full stop losses | C38: =IFERROR(AVERAGEIF(Trades!$T$2:$T$884,"Initial stop loss",Trades!$Y$2:$Y$884),0) -> -1.0260953 | E38: =IF(C38<-1.05,"Losses overshoot","OK") -> OK | F38: -1.00R = lost exactly the plan. Below -1.05R = slippage.
B39: Average R of take profits | C39: =IFERROR(AVERAGEIF(Trades!$T$2:$T$884,"Take profit",Trades!$Y$2:$Y$884),0) -> 2.0545413
B40: DRAWDOWN & PROP RULES
B41: Max closed-trade drawdown $ | C41: =MAX(Trades!$AF$2:$AF$884) -> 2246.72 | D41: 2 246.72 (1.92%) | F41: Peak-to-low of the balance.
B42: Max closed-trade drawdown % | C42: =MAX(Trades!$AG$2:$AG$884) -> 0.019223595 | D42: 2 470.08 (2.11%) | E42: =IF(C42<=C8/2,"Safe",IF(C42<=C8,"Close to limit","Breach")) -> Safe | F42: MT5 report column shows the equity drawdown (includes open trades).
...

Sheet Yearly
A1: Year | B1: Trades | C1: Wins | D1: Losses | E1: Win rate | F1: Net profit | G1: Gross profit | H1: Gross loss | I1: Profit factor | J1: Best trade | K1: Worst trade | L1: Total R | M1: Start balance | N1: Return % | O1: Limit check | P1: End balance | Q1: Cumulative net
A2: 2023 | B2: =COUNTIFS(Trades!$G$2:$G$884,$A2) -> 194 | C2: =COUNTIFS(Trades!$G$2:$G$884,$A2,Trades!$Z$2:$Z$884,"Win") -> 65 | D2: =COUNTIFS(Trades!$G$2:$G$884,$A2,Trades!$Z$2:$Z$884,"Loss") -> 129 | E2: =IFERROR(C2/B2,0) -> 0.33505155 | F2: =SUMIFS(Trades!$X$2:$X$884,Trades!$G$2:$G$884,$A2) -> 4466.65 | G2: =SUMIFS(Trades!$X$2:$X$884,Trades!$G$2:$G$884,$A2,Trades!$X$2:$X$884,">0") -> 12898.01 | H2: =SUMIFS(Trades!$X$2:$X$884,Trades!$G$2:$G$884,$A2,Trades!$X$2:$X$884,"<0") -> -8431.36 | I2: =IFERROR(G2/-H2,"no loss") -> 1.5297663 | J2: =_xlfn.MAXIFS(Trades!$X$2:$X$884,Trades!$G$2:$G$884,$A2) -> 637.98 | K2: =_xlfn.MINIFS(Trades!$X$2:$X$884,Trades!$G$2:$G$884,$A2) -> -420.99 | L2: =SUMIFS(Trades!$Y$2:$Y$884,Trades!$G$2:$G$884,$A2) -> 39.248908 | M2: =Summary!$C$5 -> 100000 | N2: =IFERROR(F2/M2,0) -> 0.0446665 | O2: =IF(F2>0,"up","down") -> up | P2: =M2+F2 -> 104466.65 | Q2: =P2-Summary!$C$5 -> 4466.65
A3: 2024 | B3: =COUNTIFS(Trades!$G$2:$G$884,$A3) -> 244 | C3: =COUNTIFS(Trades!$G$2:$G$884,$A3,Trades!$Z$2:$Z$884,"Win") -> 73 | D3: =COUNTIFS(Trades!$G$2:$G$884,$A3,Trades!$Z$2:$Z$884,"Loss") -> 167 | E3: =IFERROR(C3/B3,0) -> 0.29918033 | F3: =SUMIFS(Trades!$X$2:$X$884,Trades!$G$2:$G$884,$A3) -> 2375.02 | G3: =SUMIFS(Trades!$X$2:$X$884,Trades!$G$2:$G$884,$A3,Trades!$X$2:$X$884,">0") -> 13635.8 | H3: =SUMIFS(Trades!$X$2:$X$884,Trades!$G$2:$G$884,$A3,Trades!$X$2:$X$884,"<0") -> -11260.78 | I3: =IFERROR(G3/-H3,"no loss") -> 1.2109108 | J3: =_xlfn.MAXIFS(Trades!$X$2:$X$884,Trades!$G$2:$G$884,$A3) -> 556.6 | K3: =_xlfn.MINIFS(Trades!$X$2:$X$884,Trades!$G$2:$G$884,$A3) -> -455.88 | L3: =SUMIFS(Trades!$Y$2:$Y$884,Trades!$G$2:$G$884,$A3) -> 42.423085 | M3: =P2 -> 104466.65 | N3: =IFERROR(F3/M3,0) -> 0.02273472 | O3: =IF(F3>0,"up","down") -> up | P3: =M3+F3 -> 106841.67 | Q3: =P3-Summary!$C$5 -> 6841.67
A4: 2025 | B4: =COUNTIFS(Trades!$G$2:$G$884,$A4) -> 257 | C4: =COUNTIFS(Trades!$G$2:$G$884,$A4,Trades!$Z$2:$Z$884,"Win") -> 84 | D4: =COUNTIFS(Trades!$G$2:$G$884,$A4,Trades!$Z$2:$Z$884,"Loss") -> 170 | E4: =IFERROR(C4/B4,0) -> 0.32684825 | F4: =SUMIFS(Trades!$X$2:$X$884,Trades!$G$2:$G$884,$A4) -> 7225.36 | G4: =SUMIFS(Trades!$X$2:$X$884,Trades!$G$2:$G$884,$A4,Trades!$X$2:$X$884,">0") -> 22275.79 | H4: =SUMIFS(Trades!$X$2:$X$884,Trades!$G$2:$G$884,$A4,Trades!$X$2:$X$884,"<0") -> -15050.43 | I4: =IFERROR(G4/-H4,"no loss") -> 1.4800766 | J4: =_xlfn.MAXIFS(Trades!$X$2:$X$884,Trades!$G$2:$G$884,$A4) -> 1033.59 | K4: =_xlfn.MINIFS(Trades!$X$2:$X$884,Trades!$G$2:$G$884,$A4) -> -537.23 | L4: =SUMIFS(Trades!$Y$2:$Y$884,Trades!$G$2:$G$884,$A4) -> 52.738723 | M4: =P3 -> 106841.67 | N4: =IFERROR(F4/M4,0) -> 0.067626798 | O4: =IF(F4>0,"up","down") -> up | P4: =M4+F4 -> 114067.03 | Q4: =P4-Summary!$C$5 -> 14067.03
A5: 2026 | B5: =COUNTIFS(Trades!$G$2:$G$884,$A5) -> 188 | C5: =COUNTIFS(Trades!$G$2:$G$884,$A5,Trades!$Z$2:$Z$884,"Win") -> 60 | D5: =COUNTIFS(Trades!$G$2:$G$884,$A5,Trades!$Z$2:$Z$884,"Loss") -> 127 | E5: =IFERROR(C5/B5,0) -> 0.31914894 | F5: =SUMIFS(Trades!$X$2:$X$884,Trades!$G$2:$G$884,$A5) -> 3650.66 | G5: =SUMIFS(Trades!$X$2:$X$884,Trades!$G$2:$G$884,$A5,Trades!$X$2:$X$884,">0") -> 15524.91 | H5: =SUMIFS(Trades!$X$2:$X$884,Trades!$G$2:$G$884,$A5,Trades!$X$2:$X$884,"<0") -> -11874.25 | I5: =IFERROR(G5/-H5,"no loss") -> 1.3074434 | J5: =_xlfn.MAXIFS(Trades!$X$2:$X$884,Trades!$G$2:$G$884,$A5) -> 721.31 | K5: =_xlfn.MINIFS(Trades!$X$2:$X$884,Trades!$G$2:$G$884,$A5) -> -568.08 | L5: =SUMIFS(Trades!$Y$2:$Y$884,Trades!$G$2:$G$884,$A5) -> 42.258728 | M5: =P4 -> 114067.03 | N5: =IFERROR(F5/M5,0) -> 0.032004515 | O5: =IF(F5>0,"up","down") -> up | P5: =M5+F5 -> 117717.69 | Q5: =P5-Summary!$C$5 -> 17717.69
A7: TOTAL | B7: =SUM(B2:B5) -> 883 | C7: =SUM(C2:C5) -> 282 | D7: =SUM(D2:D5) -> 593 | E7: =IFERROR(C7/B7,0) -> 0.3193658 | F7: =SUM(F2:F5) -> 17717.69 | G7: =SUM(G2:G5) -> 64334.51 | H7: =SUM(H2:H5) -> -46616.82 | I7: =IFERROR(G7/-H7,0) -> 1.3800708 | L7: =SUM(L2:L5) -> 176.66944 | N7: =IFERROR(F7/M2,0) -> 0.1771769 | O7: =COUNTIF(F2:F5,">0")&" up / "&COUNTIF(F2:F5,"<0")&" down" -> 4 up / 0 down
A8: Partial years: the test period decides the first and last year's length.

Sheet Monthly
A1: Month | B1: Trades | C1: Wins | D1: Losses | E1: Win rate | F1: Net profit | G1: Gross profit | H1: Gross loss | I1: Profit factor | J1: Best trade | K1: Worst trade | L1: Total R | M1: Start balance | N1: Return % | O1: Limit check | P1: End balance | Q1: Cumulative net
A2: 2023-04 | B2: =COUNTIFS(Trades!$F$2:$F$884,$A2) -> 18 | C2: =COUNTIFS(Trades!$F$2:$F$884,$A2,Trades!$Z$2:$Z$884,"Win") -> 5 | D2: =COUNTIFS(Trades!$F$2:$F$884,$A2,Trades!$Z$2:$Z$884,"Loss") -> 13 | E2: =IFERROR(C2/B2,0) -> 0.27777778 | F2: =SUMIFS(Trades!$X$2:$X$884,Trades!$F$2:$F$884,$A2) -> -638.22 | G2: =SUMIFS(Trades!$X$2:$X$884,Trades!$F$2:$F$884,$A2,Trades!$X$2:$X$884,">0") -> 580.99 | H2: =SUMIFS(Trades!$X$2:$X$884,Trades!$F$2:$F$884,$A2,Trades!$X$2:$X$884,"<0") -> -1219.21 | I2: =IFERROR(G2/-H2,"no loss") -> 0.47652988 | J2: =_xlfn.MAXIFS(Trades!$X$2:$X$884,Trades!$F$2:$F$884,$A2) -> 170.07 | K2: =_xlfn.MINIFS(Trades!$X$2:$X$884,Trades!$F$2:$F$884,$A2) -> -354.48 | L2: =SUMIFS(Trades!$Y$2:$Y$884,Trades!$F$2:$F$884,$A2) -> -1.2776809 | M2: =Summary!$C$5 -> 100000 | N2: =IFERROR(F2/M2,0) -> -0.0063822 | O2: =IF(F2>0,"up","down") -> down | P2: =M2+F2 -> 99361.78 | Q2: =P2-Summary!$C$5 -> -638.22
A3: 2023-05 | B3: =COUNTIFS(Trades!$F$2:$F$884,$A3) -> 25 | C3: =COUNTIFS(Trades!$F$2:$F$884,$A3,Trades!$Z$2:$Z$884,"Win") -> 6 | D3: =COUNTIFS(Trades!$F$2:$F$884,$A3,Trades!$Z$2:$Z$884,"Loss") -> 19 | E3: =IFERROR(C3/B3,0) -> 0.24 | F3: =SUMIFS(Trades!$X$2:$X$884,Trades!$F$2:$F$884,$A3) -> -25.49 | G3: =SUMIFS(Trades!$X$2:$X$884,Trades!$F$2:$F$884,$A3,Trades!$X$2:$X$884,">0") -> 1303.66 | H3: =SUMIFS(Trades!$X$2:$X$884,Trades!$F$2:$F$884,$A3,Trades!$X$2:$X$884,"<0") -> -1329.15 | I3: =IFERROR(G3/-H3,"no loss") -> 0.98082233 | J3: =_xlfn.MAXIFS(Trades!$X$2:$X$884,Trades!$F$2:$F$884,$A3) -> 316.67 | K3: =_xlfn.MINIFS(Trades!$X$2:$X$884,Trades!$F$2:$F$884,$A3) -> -365.06 | L3: =SUMIFS(Trades!$Y$2:$Y$884,Trades!$F$2:$F$884,$A3) -> -2.5043016 | M3: =P2 -> 99361.78 | N3: =IFERROR(F3/M3,0) -> -0.00025653727 | O3: =IF(F3>0,"up","down") -> down | P3: =M3+F3 -> 99336.29 | Q3: =P3-Summary!$C$5 -> -663.71
A4: 2023-06 | B4: =COUNTIFS(Trades!$F$2:$F$884,$A4) -> 21 | C4: =COUNTIFS(Trades!$F$2:$F$884,$A4,Trades!$Z$2:$Z$884,"Win") -> 9 | D4: =COUNTIFS(Trades!$F$2:$F$884,$A4,Trades!$Z$2:$Z$884,"Loss") -> 12 | E4: =IFERROR(C4/B4,0) -> 0.42857143 | F4: =SUMIFS(Trades!$X$2:$X$884,Trades!$F$2:$F$884,$A4) -> 1177.99 | G4: =SUMIFS(Trades!$X$2:$X$884,Trades!$F$2:$F$884,$A4,Trades!$X$2:$X$884,">0") -> 1683.87 | H4: =SUMIFS(Trades!$X$2:$X$884,Trades!$F$2:$F$884,$A4,Trades!$X$2:$X$884,"<0") -> -505.88 | I4: =IFERROR(G4/-H4,"no loss") -> 3.3285957 | J4: =_xlfn.MAXIFS(Trades!$X$2:$X$884,Trades!$F$2:$F$884,$A4) -> 313.44 | K4: =_xlfn.MINIFS(Trades!$X$2:$X$884,Trades!$F$2:$F$884,$A4) -> -133.3 | L4: =SUMIFS(Trades!$Y$2:$Y$884,Trades!$F$2:$F$884,$A4) -> 12.368619 | M4: =P3 -> 99336.29 | N4: =IFERROR(F4/M4,0) -> 0.011858607 | O4: =IF(F4>0,"up","down") -> up | P4: =M4+F4 -> 100514.28 | Q4: =P4-Summary!$C$5 -> 514.28
A5: 2023-07 | B5: =COUNTIFS(Trades!$F$2:$F$884,$A5) -> 22 | C5: =COUNTIFS(Trades!$F$2:$F$884,$A5,Trades!$Z$2:$Z$884,"Win") -> 9 | D5: =COUNTIFS(Trades!$F$2:$F$884,$A5,Trades!$Z$2:$Z$884,"Loss") -> 13 | E5: =IFERROR(C5/B5,0) -> 0.40909091 | F5: =SUMIFS(Trades!$X$2:$X$884,Trades!$F$2:$F$884,$A5) -> 343.27 | G5: =SUMIFS(Trades!$X$2:$X$884,Trades!$F$2:$F$884,$A5,Trades!$X$2:$X$884,">0") -> 1330.06 | H5: =SUMIFS(Trades!$X$2:$X$884,Trades!$F$2:$F$884,$A5,Trades!$X$2:$X$884,"<0") -> -986.79 | I5: =IFERROR(G5/-H5,"no loss") -> 1.3478653 | J5: =_xlfn.MAXIFS(Trades!$X$2:$X$884,Trades!$F$2:$F$884,$A5) -> 310.69 | K5: =_xlfn.MINIFS(Trades!$X$2:$X$884,Trades!$F$2:$F$884,$A5) -> -261.23 | L5: =SUMIFS(Trades!$Y$2:$Y$884,Trades!$F$2:$F$884,$A5) -> 8.1213754 | M5: =P4 -> 100514.28 | N5: =IFERROR(F5/M5,0) -> 0.0034151366 | O5: =IF(F5>0,"up","down") -> up | P5: =M5+F5 -> 100857.55 | Q5: =P5-Summary!$C$5 -> 857.55
A6: 2023-08 | B6: =COUNTIFS(Trades!$F$2:$F$884,$A6) -> 25 | C6: =COUNTIFS(Trades!$F$2:$F$884,$A6,Trades!$Z$2:$Z$884,"Win") -> 9 | D6: =COUNTIFS(Trades!$F$2:$F$884,$A6,Trades!$Z$2:$Z$884,"Loss") -> 16 | E6: =IFERROR(C6/B6,0) -> 0.36 | F6: =SUMIFS(Trades!$X$2:$X$884,Trades!$F$2:$F$884,$A6) -> 883.52 | G6: =SUMIFS(Trades!$X$2:$X$884,Trades!$F$2:$F$884,$A6,Trades!$X$2:$X$884,">0") -> 2004.07 | H6: =SUMIFS(Trades!$X$2:$X$884,Trades!$F$2:$F$884,$A6,Trades!$X$2:$X$884,"<0") -> -1120.55 | I6: =IFERROR(G6/-H6,"no loss") -> 1.7884699 | J6: =_xlfn.MAXIFS(Trades!$X$2:$X$884,Trades!$F$2:$F$884,$A6) -> 422.82 | K6: =_xlfn.MINIFS(Trades!$X$2:$X$884,Trades!$F$2:$F$884,$A6) -> -193.14 | L6: =SUMIFS(Trades!$Y$2:$Y$884,Trades!$F$2:$F$884,$A6) -> 4.4747419 | M6: =P5 -> 100857.55 | N6: =IFERROR(F6/M6,0) -> 0.008760078 | O6: =IF(F6>0,"up","down") -> up | P6: =M6+F6 -> 101741.07 | Q6: =P6-Summary!$C$5 -> 1741.07
A7: 2023-09 | B7: =COUNTIFS(Trades!$F$2:$F$884,$A7) -> 21 | C7: =COUNTIFS(Trades!$F$2:$F$884,$A7,Trades!$Z$2:$Z$884,"Win") -> 7 | D7: =COUNTIFS(Trades!$F$2:$F$884,$A7,Trades!$Z$2:$Z$884,"Loss") -> 14 | E7: =IFERROR(C7/B7,0) -> 0.33333333 | F7: =SUMIFS(Trades!$X$2:$X$884,Trades!$F$2:$F$884,$A7) -> 1438.95 | G7: =SUMIFS(Trades!$X$2:$X$884,Trades!$F$2:$F$884,$A7,Trades!$X$2:$X$884,">0") -> 1932.3 | H7: =SUMIFS(Trades!$X$2:$X$884,Trades!$F$2:$F$884,$A7,Trades!$X$2:$X$884,"<0") -> -493.35 | I7: =IFERROR(G7/-H7,"no loss") -> 3.916692 | J7: =_xlfn.MAXIFS(Trades!$X$2:$X$884,Trades!$F$2:$F$884,$A7) -> 385.35 | K7: =_xlfn.MINIFS(Trades!$X$2:$X$884,Trades!$F$2:$F$884,$A7) -> -109.55 | L7: =SUMIFS(Trades!$Y$2:$Y$884,Trades!$F$2:$F$884,$A7) -> 4.7409601 | M7: =P6 -> 101741.07 | N7: =IFERROR(F7/M7,0) -> 0.014143256 | O7: =IF(F7>0,"up","down") -> up | P7: =M7+F7 -> 103180.02 | Q7: =P7-Summary!$C$5 -> 3180.02
A8: 2023-10 | B8: =COUNTIFS(Trades!$F$2:$F$884,$A8) -> 21 | C8: =COUNTIFS(Trades!$F$2:$F$884,$A8,Trades!$Z$2:$Z$884,"Win") -> 8 | D8: =COUNTIFS(Trades!$F$2:$F$884,$A8,Trades!$Z$2:$Z$884,"Loss") -> 13 | E8: =IFERROR(C8/B8,0) -> 0.38095238 | F8: =SUMIFS(Trades!$X$2:$X$884,Trades!$F$2:$F$884,$A8) -> 990.48 | G8: =SUMIFS(Trades!$X$2:$X$884,Trades!$F$2:$F$884,$A8,Trades!$X$2:$X$884,">0") -> 2292.81 | H8: =SUMIFS(Trades!$X$2:$X$884,Trades!$F$2:$F$884,$A8,Trades!$X$2:$X$884,"<0") -> -1302.33 | I8: =IFERROR(G8/-H8,"no loss") -> 1.7605446 | J8: =_xlfn.MAXIFS(Trades!$X$2:$X$884,Trades!$F$2:$F$884,$A8) -> 637.98 | K8: =_xlfn.MINIFS(Trades!$X$2:$X$884,Trades!$F$2:$F$884,$A8) -> -420.99 | L8: =SUMIFS(Trades!$Y$2:$Y$884,Trades!$F$2:$F$884,$A8) -> 8.2395132 | M8: =P7 -> 103180.02 | N8: =IFERROR(F8/M8,0) -> 0.0095995329 | O8: =IF(F8>0,"up","down") -> up | P8: =M8+F8 -> 104170.5 | Q8: =P8-Summary!$C$5 -> 4170.5
A9: 2023-11 | B9: =COUNTIFS(Trades!$F$2:$F$884,$A9) -> 22 | C9: =COUNTIFS(Trades!$F$2:$F$884,$A9,Trades!$Z$2:$Z$884,"Win") -> 8 | D9: =COUNTIFS(Trades!$F$2:$F$884,$A9,Trades!$Z$2:$Z$884,"Loss") -> 14 | E9: =IFERROR(C9/B9,0) -> 0.36363636 | F9: =SUMIFS(Trades!$X$2:$X$884,Trades!$F$2:$F$884,$A9) -> 724.77 | G9: =SUMIFS(Trades!$X$2:$X$884,Trades!$F$2:$F$884,$A9,Trades!$X$2:$X$884,">0") -> 1360.22 | H9: =SUMIFS(Trades!$X$2:$X$884,Trades!$F$2:$F$884,$A9,Trades!$X$2:$X$884,"<0") -> -635.45 | I9: =IFERROR(G9/-H9,"no loss") -> 2.1405618 | J9: =_xlfn.MAXIFS(Trades!$X$2:$X$884,Trades!$F$2:$F$884,$A9) -> 373.64 | K9: =_xlfn.MINIFS(Trades!$X$2:$X$884,Trades!$F$2:$F$884,$A9) -> -158.21 | L9: =SUMIFS(Trades!$Y$2:$Y$884,Trades!$F$2:$F$884,$A9) -> 8.0303055 | M9: =P8 -> 104170.5 | N9: =IFERROR(F9/M9,0) -> 0.006957536 | O9: =IF(F9>0,"up","down") -> up | P9: =M9+F9 -> 104895.27 | Q9: =P9-Summary!$C$5 -> 4895.27
A10: 2023-12 | B10: =COUNTIFS(Trades!$F$2:$F$884,$A10) -> 19 | C10: =COUNTIFS(Trades!$F$2:$F$884,$A10,Trades!$Z$2:$Z$884,"Win") -> 4 | D10: =COUNTIFS(Trades!$F$2:$F$884,$A10,Trades!$Z$2:$Z$884,"Loss") -> 15 | E10: =IFERROR(C10/B10,0) -> 0.21052632 | F10: =SUMIFS(Trades!$X$2:$X$884,Trades!$F$2:$F$884,$A10) -> -428.62 | G10: =SUMIFS(Trades!$X$2:$X$884,Trades!$F$2:$F$884,$A10,Trades!$X$2:$X$884,">0") -> 410.03 | H10: =SUMIFS(Trades!$X$2:$X$884,Trades!$F$2:$F$884,$A10,Trades!$X$2:$X$884,"<0") -> -838.65 | I10: =IFERROR(G10/-H10,"no loss") -> 0.48891671 | J10: =_xlfn.MAXIFS(Trades!$X$2:$X$884,Trades!$F$2:$F$884,$A10) -> 279.72 | K10: =_xlfn.MINIFS(Trades!$X$2:$X$884,Trades!$F$2:$F$884,$A10) -> -162.57 | L10: =SUMIFS(Trades!$Y$2:$Y$884,Trades!$F$2:$F$884,$A10) -> -2.9446249 | M10: =P9 -> 104895.27 | N10: =IFERROR(F10/M10,0) -> -0.0040861709 | O10: =IF(F10>0,"up","down") -> down | P10: =M10+F10 -> 104466.65 | Q10: =P10-Summary!$C$5 -> 4466.65
A11: 2024-01 | B11: =COUNTIFS(Trades!$F$2:$F$884,$A11) -> 22 | C11: =COUNTIFS(Trades!$F$2:$F$884,$A11,Trades!$Z$2:$Z$884,"Win") -> 10 | D11: =COUNTIFS(Trades!$F$2:$F$884,$A11,Trades!$Z$2:$Z$884,"Loss") -> 12 | E11: =IFERROR(C11/B11,0) -> 0.45454545 | F11: =SUMIFS(Trades!$X$2:$X$884,Trades!$F$2:$F$884,$A11) -> 1010.77 | G11: =SUMIFS(Trades!$X$2:$X$884,Trades!$F$2:$F$884,$A11,Trades!$X$2:$X$884,">0") -> 1656.1 | H11: =SUMIFS(Trades!$X$2:$X$884,Trades!$F$2:$F$884,$A11,Trades!$X$2:$X$884,"<0") -> -645.33 | I11: =IFERROR(G11/-H11,"no loss") -> 2.5662839 | J11: =_xlfn.MAXIFS(Trades!$X$2:$X$884,Trades!$F$2:$F$884,$A11) -> 525.69 | K11: =_xlfn.MINIFS(Trades!$X$2:$X$884,Trades!$F$2:$F$884,$A11) -> -140.13 | L11: =SUMIFS(Trades!$Y$2:$Y$884,Trades!$F$2:$F$884,$A11) -> 11.090573 | M11: =P10 -> 104466.65 | N11: =IFERROR(F11/M11,0) -> 0.009675528 | O11: =IF(F11>0,"up","down") -> up | P11: =M11+F11 -> 105477.42 | Q11: =P11-Summary!$C$5 -> 5477.42
A12: 2024-02 | B12: =COUNTIFS(Trades!$F$2:$F$884,$A12) -> 19 | C12: =COUNTIFS(Trades!$F$2:$F$884,$A12,Trades!$Z$2:$Z$884,"Win") -> 5 | D12: =COUNTIFS(Trades!$F$2:$F$884,$A12,Trades!$Z$2:$Z$884,"Loss") -> 14 | E12: =IFERROR(C12/B12,0) -> 0.26315789 | F12: =SUMIFS(Trades!$X$2:$X$884,Trades!$F$2:$F$884,$A12) -> 1018.44 | G12: =SUMIFS(Trades!$X$2:$X$884,Trades!$F$2:$F$884,$A12,Trades!$X$2:$X$884,">0") -> 1443.47 | H12: =SUMIFS(Trades!$X$2:$X$884,Trades!$F$2:$F$884,$A12,Trades!$X$2:$X$884,"<0") -> -425.03 | I12: =IFERROR(G12/-H12,"no loss") -> 3.3961603 | J12: =_xlfn.MAXIFS(Trades!$X$2:$X$884,Trades!$F$2:$F$884,$A12) -> 498.73 | K12: =_xlfn.MINIFS(Trades!$X$2:$X$884,Trades!$F$2:$F$884,$A12) -> -130.57 | L12: =SUMIFS(Trades!$Y$2:$Y$884,Trades!$F$2:$F$884,$A12) -> 2.6344646 | M12: =P11 -> 105477.42 | N12: =IFERROR(F12/M12,0) -> 0.0096555263 | O12: =IF(F12>0,"up","down") -> up | P12: =M12+F12 -> 106495.86 | Q12: =P12-Summary!$C$5 -> 6495.86
A13: 2024-03 | B13: =COUNTIFS(Trades!$F$2:$F$884,$A13) -> 19 | C13: =COUNTIFS(Trades!$F$2:$F$884,$A13,Trades!$Z$2:$Z$884,"Win") -> 5 | D13: =COUNTIFS(Trades!$F$2:$F$884,$A13,Trades!$Z$2:$Z$884,"Loss") -> 14 | E13: =IFERROR(C13/B13,0) -> 0.26315789 | F13: =SUMIFS(Trades!$X$2:$X$884,Trades!$F$2:$F$884,$A13) -> -618.59 | G13: =SUMIFS(Trades!$X$2:$X$884,Trades!$F$2:$F$884,$A13,Trades!$X$2:$X$884,">0") -> 450.89 | H13: =SUMIFS(Trades!$X$2:$X$884,Trades!$F$2:$F$884,$A13,Trades!$X$2:$X$884,"<0") -> -1069.48 | I13: =IFERROR(G13/-H13,"no loss") -> 0.42159741 | J13: =_xlfn.MAXIFS(Trades!$X$2:$X$884,Trades!$F$2:$F$884,$A13) -> 126.46 | K13: =_xlfn.MINIFS(Trades!$X$2:$X$884,Trades!$F$2:$F$884,$A13) -> -242.48 | L13: =SUMIFS(Trades!$Y$2:$Y$884,Trades!$F$2:$F$884,$A13) -> 0.77355524 | M13: =P12 -> 106495.86 | N13: =IFERROR(F13/M13,0) -> -0.0058085826 | O13: =IF(F13>0,"up","down") -> down | P13: =M13+F13 -> 105877.27 | Q13: =P13-Summary!$C$5 -> 5877.27
A14: 2024-04 | B14: =COUNTIFS(Trades!$F$2:$F$884,$A14) -> 23 | C14: =COUNTIFS(Trades!$F$2:$F$884,$A14,Trades!$Z$2:$Z$884,"Win") -> 5 | D14: =COUNTIFS(Trades!$F$2:$F$884,$A14,Trades!$Z$2:$Z$884,"Loss") -> 18 | E14: =IFERROR(C14/B14,0) -> 0.2173913 | F14: =SUMIFS(Trades!$X$2:$X$884,Trades!$F$2:$F$884,$A14) -> -540.62 | G14: =SUMIFS(Trades!$X$2:$X$884,Trades!$F$2:$F$884,$A14,Trades!$X$2:$X$884,">0") -> 1375.82 | H14: =SUMIFS(Trades!$X$2:$X$884,Trades!$F$2:$F$884,$A14,Trades!$X$2:$X$884,"<0") -> -1916.44 | I14: =IFERROR(G14/-H14,"no loss") -> 0.71790403 | J14: =_xlfn.MAXIFS(Trades!$X$2:$X$884,Trades!$F$2:$F$884,$A14) -> 405.39 | K14: =_xlfn.MINIFS(Trades!$X$2:$X$884,Trades!$F$2:$F$884,$A14) -> -455.88 | L14: =SUMIFS(Trades!$Y$2:$Y$884,Trades!$F$2:$F$884,$A14) -> -2.2145602 | M14: =P13 -> 105877.27 | N14: =IFERROR(F14/M14,0) -> -0.0051061007 | O14: =IF(F14>0,"up","down") -> down | P14: =M14+F14 -> 105336.65 | Q14: =P14-Summary!$C$5 -> 5336.65
... A43: 2026-09 | B43: =COUNTIFS(Trades!$F$2:$F$884,$A43) -> 20 | C43: =COUNTIFS(Trades!$F$2:$F$884,$A43,Trades!$Z$2:$Z$884,"Win") -> 9 | D43: =COUNTIFS(Trades!$F$2:$F$884,$A43,Trades!$Z$2:$Z$884,"Loss") -> 10 | E43: =IFERROR(C43/B43,0) -> 0.45 | F43: =SUMIFS(Trades!$X$2:$X$884,Trades!$F$2:$F$884,$A43) -> 1106.43 | G43: =SUMIFS(Trades!$X$2:$X$884,Trades!$F$2:$F$884,$A43,Trades!$X$2:$X$884,">0") -> 1517.85 | H43: =SUMIFS(Trades!$X$2:$X$884,Trades!$F$2:$F$884,$A43,Trades!$X$2:$X$884,"<0") -> -411.42 | I43: =IFERROR(G43/-H43,"no loss") -> 3.6892956 | J43: =_xlfn.MAXIFS(Trades!$X$2:$X$884,Trades!$F$2:$F$884,$A43) -> 720.14 | K43: =_xlfn.MINIFS(Trades!$X$2:$X$884,Trades!$F$2:$F$884,$A43) -> -180.88 | L43: =SUMIFS(Trades!$Y$2:$Y$884,Trades!$F$2:$F$884,$A43) -> 13.037907 | M43: =P42 -> 116611.26 | N43: =IFERROR(F43/M43,0) -> 0.0094881918 | O43: =IF(F43>0,"up","down") -> up | P43: =M43+F43 -> 117717.69 | Q43: =P43-Summary!$C$5 -> 17717.69
A45: TOTAL | B45: =SUM(B2:B43) -> 883 | C45: =SUM(C2:C43) -> 282 | D45: =SUM(D2:D43) -> 593 | E45: =IFERROR(C45/B45,0) -> 0.3193658 | F45: =SUM(F2:F43) -> 17717.69 | G45: =SUM(G2:G43) -> 64334.51 | H45: =SUM(H2:H43) -> -46616.82 | I45: =IFERROR(G45/-H45,0) -> 1.3800708 | L45: =SUM(L2:L43) -> 176.66944 | N45: =IFERROR(F45/M2,0) -> 0.1771769 | O45: =COUNTIF(F2:F43,">0")&" up / "&COUNTIF(F2:F43,"<0")&" down" -> 28 up / 14 down

Sheet Calendar
A1: Net profit by month ($) - green = profit, red = loss
A3: Year | B3: Jan | C3: Feb | D3: Mar | E3: Apr | F3: May | G3: Jun | H3: Jul | I3: Aug | J3: Sep | K3: Oct | L3: Nov | M3: Dec | N3: Year total | O3: Return %
A4: 2023 | B4: =SUMIFS(Trades!$X$2:$X$884,Trades!$F$2:$F$884,"2023-01") -> 0 | C4: =SUMIFS(Trades!$X$2:$X$884,Trades!$F$2:$F$884,"2023-02") -> 0 | D4: =SUMIFS(Trades!$X$2:$X$884,Trades!$F$2:$F$884,"2023-03") -> 0 | E4: =SUMIFS(Trades!$X$2:$X$884,Trades!$F$2:$F$884,"2023-04") -> -638.22 | F4: =SUMIFS(Trades!$X$2:$X$884,Trades!$F$2:$F$884,"2023-05") -> -25.49 | G4: =SUMIFS(Trades!$X$2:$X$884,Trades!$F$2:$F$884,"2023-06") -> 1177.99 | H4: =SUMIFS(Trades!$X$2:$X$884,Trades!$F$2:$F$884,"2023-07") -> 343.27 | I4: =SUMIFS(Trades!$X$2:$X$884,Trades!$F$2:$F$884,"2023-08") -> 883.52 | J4: =SUMIFS(Trades!$X$2:$X$884,Trades!$F$2:$F$884,"2023-09") -> 1438.95 | K4: =SUMIFS(Trades!$X$2:$X$884,Trades!$F$2:$F$884,"2023-10") -> 990.48 | L4: =SUMIFS(Trades!$X$2:$X$884,Trades!$F$2:$F$884,"2023-11") -> 724.77 | M4: =SUMIFS(Trades!$X$2:$X$884,Trades!$F$2:$F$884,"2023-12") -> -428.62 | N4: =SUM(B4:M4) -> 4466.65 | O4: =IFERROR(N4/Summary!$C$5,0) -> 0.0446665
A5: 2024 | B5: =SUMIFS(Trades!$X$2:$X$884,Trades!$F$2:$F$884,"2024-01") -> 1010.77 | C5: =SUMIFS(Trades!$X$2:$X$884,Trades!$F$2:$F$884,"2024-02") -> 1018.44 | D5: =SUMIFS(Trades!$X$2:$X$884,Trades!$F$2:$F$884,"2024-03") -> -618.59 | E5: =SUMIFS(Trades!$X$2:$X$884,Trades!$F$2:$F$884,"2024-04") -> -540.62 | F5: =SUMIFS(Trades!$X$2:$X$884,Trades!$F$2:$F$884,"2024-05") -> 298.78 | G5: =SUMIFS(Trades!$X$2:$X$884,Trades!$F$2:$F$884,"2024-06") -> 79.97 | H5: =SUMIFS(Trades!$X$2:$X$884,Trades!$F$2:$F$884,"2024-07") -> 344.55 | I5: =SUMIFS(Trades!$X$2:$X$884,Trades!$F$2:$F$884,"2024-08") -> 173.58 | J5: =SUMIFS(Trades!$X$2:$X$884,Trades!$F$2:$F$884,"2024-09") -> -290 | K5: =SUMIFS(Trades!$X$2:$X$884,Trades!$F$2:$F$884,"2024-10") -> -328 | L5: =SUMIFS(Trades!$X$2:$X$884,Trades!$F$2:$F$884,"2024-11") -> 341.46 | M5: =SUMIFS(Trades!$X$2:$X$884,Trades!$F$2:$F$884,"2024-12") -> 884.68 | N5: =SUM(B5:M5) -> 2375.02 | O5: =IFERROR(N5/Summary!$C$5,0) -> 0.0237502
A6: 2025 | B6: =SUMIFS(Trades!$X$2:$X$884,Trades!$F$2:$F$884,"2025-01") -> 1042.63 | C6: =SUMIFS(Trades!$X$2:$X$884,Trades!$F$2:$F$884,"2025-02") -> 268.75 | D6: =SUMIFS(Trades!$X$2:$X$884,Trades!$F$2:$F$884,"2025-03") -> 709.31 | E6: =SUMIFS(Trades!$X$2:$X$884,Trades!$F$2:$F$884,"2025-04") -> 2501.59 | F6: =SUMIFS(Trades!$X$2:$X$884,Trades!$F$2:$F$884,"2025-05") -> 358.91 | G6: =SUMIFS(Trades!$X$2:$X$884,Trades!$F$2:$F$884,"2025-06") -> 345.34 | H6: =SUMIFS(Trades!$X$2:$X$884,Trades!$F$2:$F$884,"2025-07") -> 836.53 | I6: =SUMIFS(Trades!$X$2:$X$884,Trades!$F$2:$F$884,"2025-08") -> -140.64 | J6: =SUMIFS(Trades!$X$2:$X$884,Trades!$F$2:$F$884,"2025-09") -> -95.91 | K6: =SUMIFS(Trades!$X$2:$X$884,Trades!$F$2:$F$884,"2025-10") -> 1221.66 | L6: =SUMIFS(Trades!$X$2:$X$884,Trades!$F$2:$F$884,"2025-11") -> 923.27 | M6: =SUMIFS(Trades!$X$2:$X$884,Trades!$F$2:$F$884,"2025-12") -> -746.08 | N6: =SUM(B6:M6) -> 7225.36 | O6: =IFERROR(N6/Summary!$C$5,0) -> 0.0722536
A7: 2026 | B7: =SUMIFS(Trades!$X$2:$X$884,Trades!$F$2:$F$884,"2026-01") -> 487.9 | C7: =SUMIFS(Trades!$X$2:$X$884,Trades!$F$2:$F$884,"2026-02") -> 1186.81 | D7: =SUMIFS(Trades!$X$2:$X$884,Trades!$F$2:$F$884,"2026-03") -> -321.11 | E7: =SUMIFS(Trades!$X$2:$X$884,Trades!$F$2:$F$884,"2026-04") -> -129 | F7: =SUMIFS(Trades!$X$2:$X$884,Trades!$F$2:$F$884,"2026-05") -> 810.02 | G7: =SUMIFS(Trades!$X$2:$X$884,Trades!$F$2:$F$884,"2026-06") -> -589.22 | H7: =SUMIFS(Trades!$X$2:$X$884,Trades!$F$2:$F$884,"2026-07") -> -175.57 | I7: =SUMIFS(Trades!$X$2:$X$884,Trades!$F$2:$F$884,"2026-08") -> 1274.4 | J7: =SUMIFS(Trades!$X$2:$X$884,Trades!$F$2:$F$884,"2026-09") -> 1106.43 | K7: =SUMIFS(Trades!$X$2:$X$884,Trades!$F$2:$F$884,"2026-10") -> 0 | L7: =SUMIFS(Trades!$X$2:$X$884,Trades!$F$2:$F$884,"2026-11") -> 0 | M7: =SUMIFS(Trades!$X$2:$X$884,Trades!$F$2:$F$884,"2026-12") -> 0 | N7: =SUM(B7:M7) -> 3650.66 | O7: =IFERROR(N7/Summary!$C$5,0) -> 0.0365066
A9: Trades per month
A10: Year | B10: Jan | C10: Feb | D10: Mar | E10: Apr | F10: May | G10: Jun | H10: Jul | I10: Aug | J10: Sep | K10: Oct | L10: Nov | M10: Dec | N10: Year total
A11: 2023 | B11: =COUNTIFS(Trades!$F$2:$F$884,"2023-01") -> 0 | C11: =COUNTIFS(Trades!$F$2:$F$884,"2023-02") -> 0 | D11: =COUNTIFS(Trades!$F$2:$F$884,"2023-03") -> 0 | E11: =COUNTIFS(Trades!$F$2:$F$884,"2023-04") -> 18 | F11: =COUNTIFS(Trades!$F$2:$F$884,"2023-05") -> 25 | G11: =COUNTIFS(Trades!$F$2:$F$884,"2023-06") -> 21 | H11: =COUNTIFS(Trades!$F$2:$F$884,"2023-07") -> 22 | I11: =COUNTIFS(Trades!$F$2:$F$884,"2023-08") -> 25 | J11: =COUNTIFS(Trades!$F$2:$F$884,"2023-09") -> 21 | K11: =COUNTIFS(Trades!$F$2:$F$884,"2023-10") -> 21 | L11: =COUNTIFS(Trades!$F$2:$F$884,"2023-11") -> 22 | M11: =COUNTIFS(Trades!$F$2:$F$884,"2023-12") -> 19 | N11: =SUM(B11:M11) -> 194
A12: 2024 | B12: =COUNTIFS(Trades!$F$2:$F$884,"2024-01") -> 22 | C12: =COUNTIFS(Trades!$F$2:$F$884,"2024-02") -> 19 | D12: =COUNTIFS(Trades!$F$2:$F$884,"2024-03") -> 19 | E12: =COUNTIFS(Trades!$F$2:$F$884,"2024-04") -> 23 | F12: =COUNTIFS(Trades!$F$2:$F$884,"2024-05") -> 22 | G12: =COUNTIFS(Trades!$F$2:$F$884,"2024-06") -> 17 | H12: =COUNTIFS(Trades!$F$2:$F$884,"2024-07") -> 21 | I12: =COUNTIFS(Trades!$F$2:$F$884,"2024-08") -> 22 | J12: =COUNTIFS(Trades!$F$2:$F$884,"2024-09") -> 21 | K12: =COUNTIFS(Trades!$F$2:$F$884,"2024-10") -> 21 | L12: =COUNTIFS(Trades!$F$2:$F$884,"2024-11") -> 18 | M12: =COUNTIFS(Trades!$F$2:$F$884,"2024-12") -> 19 | N12: =SUM(B12:M12) -> 244
A13: 2025 | B13: =COUNTIFS(Trades!$F$2:$F$884,"2025-01") -> 20 | C13: =COUNTIFS(Trades!$F$2:$F$884,"2025-02") -> 20 | D13: =COUNTIFS(Trades!$F$2:$F$884,"2025-03") -> 21 | E13: =COUNTIFS(Trades!$F$2:$F$884,"2025-04") -> 19 | F13: =COUNTIFS(Trades!$F$2:$F$884,"2025-05") -> 24 | G13: =COUNTIFS(Trades!$F$2:$F$884,"2025-06") -> 21 | H13: =COUNTIFS(Trades!$F$2:$F$884,"2025-07") -> 23 | I13: =COUNTIFS(Trades!$F$2:$F$884,"2025-08") -> 21 | J13: =COUNTIFS(Trades!$F$2:$F$884,"2025-09") -> 19 | K13: =COUNTIFS(Trades!$F$2:$F$884,"2025-10") -> 27 | L13: =COUNTIFS(Trades!$F$2:$F$884,"2025-11") -> 19 | M13: =COUNTIFS(Trades!$F$2:$F$884,"2025-12") -> 23 | N13: =SUM(B13:M13) -> 257
A14: 2026 | B14: =COUNTIFS(Trades!$F$2:$F$884,"2026-01") -> 21 | C14: =COUNTIFS(Trades!$F$2:$F$884,"2026-02") -> 22 | D14: =COUNTIFS(Trades!$F$2:$F$884,"2026-03") -> 23 | E14: =COUNTIFS(Trades!$F$2:$F$884,"2026-04") -> 21 | F14: =COUNTIFS(Trades!$F$2:$F$884,"2026-05") -> 21 | G14: =COUNTIFS(Trades!$F$2:$F$884,"2026-06") -> 22 | H14: =COUNTIFS(Trades!$F$2:$F$884,"2026-07") -> 20 | I14: =COUNTIFS(Trades!$F$2:$F$884,"2026-08") -> 18 | J14: =COUNTIFS(Trades!$F$2:$F$884,"2026-09") -> 20 | K14: =COUNTIFS(Trades!$F$2:$F$884,"2026-10") -> 0 | L14: =COUNTIFS(Trades!$F$2:$F$884,"2026-11") -> 0 | M14: =COUNTIFS(Trades!$F$2:$F$884,"2026-12") -> 0 | N14: =SUM(B14:M14) -> 188
A16: Win rate per month
A17: Year | B17: Jan | C17: Feb | D17: Mar | E17: Apr | F17: May | G17: Jun | H17: Jul | I17: Aug | J17: Sep | K17: Oct | L17: Nov | M17: Dec
A18: 2023 | B18: =IFERROR(COUNTIFS(Trades!$F$2:$F$884,"2023-01",Trades!$Z$2:$Z$884,"Win")/COUNTIFS(Trades!$F$2:$F$884,"2023-01"),"") | C18: =IFERROR(COUNTIFS(Trades!$F$2:$F$884,"2023-02",Trades!$Z$2:$Z$884,"Win")/COUNTIFS(Trades!$F$2:$F$884,"2023-02"),"") | D18: =IFERROR(COUNTIFS(Trades!$F$2:$F$884,"2023-03",Trades!$Z$2:$Z$884,"Win")/COUNTIFS(Trades!$F$2:$F$884,"2023-03"),"") | E18: =IFERROR(COUNTIFS(Trades!$F$2:$F$884,"2023-04",Trades!$Z$2:$Z$884,"Win")/COUNTIFS(Trades!$F$2:$F$884,"2023-04"),"") -> 0.27777778 | F18: =IFERROR(COUNTIFS(Trades!$F$2:$F$884,"2023-05",Trades!$Z$2:$Z$884,"Win")/COUNTIFS(Trades!$F$2:$F$884,"2023-05"),"") -> 0.24 | G18: =IFERROR(COUNTIFS(Trades!$F$2:$F$884,"2023-06",Trades!$Z$2:$Z$884,"Win")/COUNTIFS(Trades!$F$2:$F$884,"2023-06"),"") -> 0.42857143 | H18: =IFERROR(COUNTIFS(Trades!$F$2:$F$884,"2023-07",Trades!$Z$2:$Z$884,"Win")/COUNTIFS(Trades!$F$2:$F$884,"2023-07"),"") -> 0.40909091 | I18: =IFERROR(COUNTIFS(Trades!$F$2:$F$884,"2023-08",Trades!$Z$2:$Z$884,"Win")/COUNTIFS(Trades!$F$2:$F$884,"2023-08"),"") -> 0.36 | J18: =IFERROR(COUNTIFS(Trades!$F$2:$F$884,"2023-09",Trades!$Z$2:$Z$884,"Win")/COUNTIFS(Trades!$F$2:$F$884,"2023-09"),"") -> 0.33333333 | K18: =IFERROR(COUNTIFS(Trades!$F$2:$F$884,"2023-10",Trades!$Z$2:$Z$884,"Win")/COUNTIFS(Trades!$F$2:$F$884,"2023-10"),"") -> 0.38095238 | L18: =IFERROR(COUNTIFS(Trades!$F$2:$F$884,"2023-11",Trades!$Z$2:$Z$884,"Win")/COUNTIFS(Trades!$F$2:$F$884,"2023-11"),"") -> 0.36363636 | M18: =IFERROR(COUNTIFS(Trades!$F$2:$F$884,"2023-12",Trades!$Z$2:$Z$884,"Win")/COUNTIFS(Trades!$F$2:$F$884,"2023-12"),"") -> 0.21052632
A19: 2024 | B19: =IFERROR(COUNTIFS(Trades!$F$2:$F$884,"2024-01",Trades!$Z$2:$Z$884,"Win")/COUNTIFS(Trades!$F$2:$F$884,"2024-01"),"") -> 0.45454545 | C19: =IFERROR(COUNTIFS(Trades!$F$2:$F$884,"2024-02",Trades!$Z$2:$Z$884,"Win")/COUNTIFS(Trades!$F$2:$F$884,"2024-02"),"") -> 0.26315789 | D19: =IFERROR(COUNTIFS(Trades!$F$2:$F$884,"2024-03",Trades!$Z$2:$Z$884,"Win")/COUNTIFS(Trades!$F$2:$F$884,"2024-03"),"") -> 0.26315789 | E19: =IFERROR(COUNTIFS(Trades!$F$2:$F$884,"2024-04",Trades!$Z$2:$Z$884,"Win")/COUNTIFS(Trades!$F$2:$F$884,"2024-04"),"") -> 0.2173913 | F19: =IFERROR(COUNTIFS(Trades!$F$2:$F$884,"2024-05",Trades!$Z$2:$Z$884,"Win")/COUNTIFS(Trades!$F$2:$F$884,"2024-05"),"") -> 0.31818182 | G19: =IFERROR(COUNTIFS(Trades!$F$2:$F$884,"2024-06",Trades!$Z$2:$Z$884,"Win")/COUNTIFS(Trades!$F$2:$F$884,"2024-06"),"") -> 0.29411765 | H19: =IFERROR(COUNTIFS(Trades!$F$2:$F$884,"2024-07",Trades!$Z$2:$Z$884,"Win")/COUNTIFS(Trades!$F$2:$F$884,"2024-07"),"") -> 0.33333333 | I19: =IFERROR(COUNTIFS(Trades!$F$2:$F$884,"2024-08",Trades!$Z$2:$Z$884,"Win")/COUNTIFS(Trades!$F$2:$F$884,"2024-08"),"") -> 0.31818182 | J19: =IFERROR(COUNTIFS(Trades!$F$2:$F$884,"2024-09",Trades!$Z$2:$Z$884,"Win")/COUNTIFS(Trades!$F$2:$F$884,"2024-09"),"") -> 0.23809524 | K19: =IFERROR(COUNTIFS(Trades!$F$2:$F$884,"2024-10",Trades!$Z$2:$Z$884,"Win")/COUNTIFS(Trades!$F$2:$F$884,"2024-10"),"") -> 0.23809524 | L19: =IFERROR(COUNTIFS(Trades!$F$2:$F$884,"2024-11",Trades!$Z$2:$Z$884,"Win")/COUNTIFS(Trades!$F$2:$F$884,"2024-11"),"") -> 0.33333333 | M19: =IFERROR(COUNTIFS(Trades!$F$2:$F$884,"2024-12",Trades!$Z$2:$Z$884,"Win")/COUNTIFS(Trades!$F$2:$F$884,"2024-12"),"") -> 0.31578947
A20: 2025 | B20: =IFERROR(COUNTIFS(Trades!$F$2:$F$884,"2025-01",Trades!$Z$2:$Z$884,"Win")/COUNTIFS(Trades!$F$2:$F$884,"2025-01"),"") -> 0.35 | C20: =IFERROR(COUNTIFS(Trades!$F$2:$F$884,"2025-02",Trades!$Z$2:$Z$884,"Win")/COUNTIFS(Trades!$F$2:$F$884,"2025-02"),"") -> 0.45 | D20: =IFERROR(COUNTIFS(Trades!$F$2:$F$884,"2025-03",Trades!$Z$2:$Z$884,"Win")/COUNTIFS(Trades!$F$2:$F$884,"2025-03"),"") -> 0.23809524 | E20: =IFERROR(COUNTIFS(Trades!$F$2:$F$884,"2025-04",Trades!$Z$2:$Z$884,"Win")/COUNTIFS(Trades!$F$2:$F$884,"2025-04"),"") -> 0.26315789 | F20: =IFERROR(COUNTIFS(Trades!$F$2:$F$884,"2025-05",Trades!$Z$2:$Z$884,"Win")/COUNTIFS(Trades!$F$2:$F$884,"2025-05"),"") -> 0.33333333 | G20: =IFERROR(COUNTIFS(Trades!$F$2:$F$884,"2025-06",Trades!$Z$2:$Z$884,"Win")/COUNTIFS(Trades!$F$2:$F$884,"2025-06"),"") -> 0.38095238 | H20: =IFERROR(COUNTIFS(Trades!$F$2:$F$884,"2025-07",Trades!$Z$2:$Z$884,"Win")/COUNTIFS(Trades!$F$2:$F$884,"2025-07"),"") -> 0.39130435 | I20: =IFERROR(COUNTIFS(Trades!$F$2:$F$884,"2025-08",Trades!$Z$2:$Z$884,"Win")/COUNTIFS(Trades!$F$2:$F$884,"2025-08"),"") -> 0.19047619 | J20: =IFERROR(COUNTIFS(Trades!$F$2:$F$884,"2025-09",Trades!$Z$2:$Z$884,"Win")/COUNTIFS(Trades!$F$2:$F$884,"2025-09"),"") -> 0.26315789 | K20: =IFERROR(COUNTIFS(Trades!$F$2:$F$884,"2025-10",Trades!$Z$2:$Z$884,"Win")/COUNTIFS(Trades!$F$2:$F$884,"2025-10"),"") -> 0.40740741 | L20: =IFERROR(COUNTIFS(Trades!$F$2:$F$884,"2025-11",Trades!$Z$2:$Z$884,"Win")/COUNTIFS(Trades!$F$2:$F$884,"2025-11"),"") -> 0.47368421 | M20: =IFERROR(COUNTIFS(Trades!$F$2:$F$884,"2025-12",Trades!$Z$2:$Z$884,"Win")/COUNTIFS(Trades!$F$2:$F$884,"2025-12"),"") -> 0.17391304
A21: 2026 | B21: =IFERROR(COUNTIFS(Trades!$F$2:$F$884,"2026-01",Trades!$Z$2:$Z$884,"Win")/COUNTIFS(Trades!$F$2:$F$884,"2026-01"),"") -> 0.33333333 | C21: =IFERROR(COUNTIFS(Trades!$F$2:$F$884,"2026-02",Trades!$Z$2:$Z$884,"Win")/COUNTIFS(Trades!$F$2:$F$884,"2026-02"),"") -> 0.31818182 | D21: =IFERROR(COUNTIFS(Trades!$F$2:$F$884,"2026-03",Trades!$Z$2:$Z$884,"Win")/COUNTIFS(Trades!$F$2:$F$884,"2026-03"),"") -> 0.26086957 | E21: =IFERROR(COUNTIFS(Trades!$F$2:$F$884,"2026-04",Trades!$Z$2:$Z$884,"Win")/COUNTIFS(Trades!$F$2:$F$884,"2026-04"),"") -> 0.42857143 | F21: =IFERROR(COUNTIFS(Trades!$F$2:$F$884,"2026-05",Trades!$Z$2:$Z$884,"Win")/COUNTIFS(Trades!$F$2:$F$884,"2026-05"),"") -> 0.33333333 | G21: =IFERROR(COUNTIFS(Trades!$F$2:$F$884,"2026-06",Trades!$Z$2:$Z$884,"Win")/COUNTIFS(Trades!$F$2:$F$884,"2026-06"),"") -> 0.18181818 | H21: =IFERROR(COUNTIFS(Trades!$F$2:$F$884,"2026-07",Trades!$Z$2:$Z$884,"Win")/COUNTIFS(Trades!$F$2:$F$884,"2026-07"),"") -> 0.2 | I21: =IFERROR(COUNTIFS(Trades!$F$2:$F$884,"2026-08",Trades!$Z$2:$Z$884,"Win")/COUNTIFS(Trades!$F$2:$F$884,"2026-08"),"") -> 0.38888889 | J21: =IFERROR(COUNTIFS(Trades!$F$2:$F$884,"2026-09",Trades!$Z$2:$Z$884,"Win")/COUNTIFS(Trades!$F$2:$F$884,"2026-09"),"") -> 0.45 | K21: =IFERROR(COUNTIFS(Trades!$F$2:$F$884,"2026-10",Trades!$Z$2:$Z$884,"Win")/COUNTIFS(Trades!$F$2:$F$884,"2026-10"),"") | L21: =IFERROR(COUNTIFS(Trades!$F$2:$F$884,"2026-11",Trades!$Z$2:$Z$884,"Win")/COUNTIFS(Trades!$F$2:$F$884,"2026-11"),"") | M21: =IFERROR(COUNTIFS(Trades!$F$2:$F$884,"2026-12",Trades!$Z$2:$Z$884,"Win")/COUNTIFS(Trades!$F$2:$F$884,"2026-12"),"")

Sheet Weekly
A1: Week (Mon) | B1: Trades | C1: Wins | D1: Losses | E1: Win rate | F1: Net profit | G1: Gross profit | H1: Gross loss | I1: Profit factor | J1: Best trade | K1: Worst trade | L1: Total R | M1: Start balance | N1: Return % | O1: Limit check | P1: End balance | Q1: Cumulative net
A2: 45019 | B2: =COUNTIFS(Trades!$E$2:$E$884,$A2) -> 3 | C2: =COUNTIFS(Trades!$E$2:$E$884,$A2,Trades!$Z$2:$Z$884,"Win") -> 2 | D2: =COUNTIFS(Trades!$E$2:$E$884,$A2,Trades!$Z$2:$Z$884,"Loss") -> 1 | E2: =IFERROR(C2/B2,0) -> 0.66666667 | F2: =SUMIFS(Trades!$X$2:$X$884,Trades!$E$2:$E$884,$A2) -> 224.34 | G2: =SUMIFS(Trades!$X$2:$X$884,Trades!$E$2:$E$884,$A2,Trades!$X$2:$X$884,">0") -> 226.24 | H2: =SUMIFS(Trades!$X$2:$X$884,Trades!$E$2:$E$884,$A2,Trades!$X$2:$X$884,"<0") -> -1.9 | I2: =IFERROR(G2/-H2,"no loss") -> 119.07368 | J2: =_xlfn.MAXIFS(Trades!$X$2:$X$884,Trades!$E$2:$E$884,$A2) -> 140.56 | K2: =_xlfn.MINIFS(Trades!$X$2:$X$884,Trades!$E$2:$E$884,$A2) -> -1.9 | L2: =SUMIFS(Trades!$Y$2:$Y$884,Trades!$E$2:$E$884,$A2) -> 4.0614034 | M2: =Summary!$C$5 -> 100000 | N2: =IFERROR(F2/M2,0) -> 0.0022434 | O2: =IF(F2<0,"down week","") | P2: =M2+F2 -> 100224.34 | Q2: =P2-Summary!$C$5 -> 224.34
A3: 45026 | B3: =COUNTIFS(Trades!$E$2:$E$884,$A3) -> 7 | C3: =COUNTIFS(Trades!$E$2:$E$884,$A3,Trades!$Z$2:$Z$884,"Win") -> 1 | D3: =COUNTIFS(Trades!$E$2:$E$884,$A3,Trades!$Z$2:$Z$884,"Loss") -> 6 | E3: =IFERROR(C3/B3,0) -> 0.14285714 | F3: =SUMIFS(Trades!$X$2:$X$884,Trades!$E$2:$E$884,$A3) -> -619.87 | G3: =SUMIFS(Trades!$X$2:$X$884,Trades!$E$2:$E$884,$A3,Trades!$X$2:$X$884,">0") -> 60.72 | H3: =SUMIFS(Trades!$X$2:$X$884,Trades!$E$2:$E$884,$A3,Trades!$X$2:$X$884,"<0") -> -680.59 | I3: =IFERROR(G3/-H3,"no loss") -> 0.089216709 | J3: =_xlfn.MAXIFS(Trades!$X$2:$X$884,Trades!$E$2:$E$884,$A3) -> 60.72 | K3: =_xlfn.MINIFS(Trades!$X$2:$X$884,Trades!$E$2:$E$884,$A3) -> -354.48 | L3: =SUMIFS(Trades!$Y$2:$Y$884,Trades!$E$2:$E$884,$A3) -> -4.1516873 | M3: =P2 -> 100224.34 | N3: =IFERROR(F3/M3,0) -> -0.006184825 | O3: =IF(F3<0,"down week","") -> down week | P3: =M3+F3 -> 99604.47 | Q3: =P3-Summary!$C$5 -> -395.53
A4: 45033 | B4: =COUNTIFS(Trades!$E$2:$E$884,$A4) -> 4 | C4: =COUNTIFS(Trades!$E$2:$E$884,$A4,Trades!$Z$2:$Z$884,"Win") -> 2 | D4: =COUNTIFS(Trades!$E$2:$E$884,$A4,Trades!$Z$2:$Z$884,"Loss") -> 2 | E4: =IFERROR(C4/B4,0) -> 0.5 | F4: =SUMIFS(Trades!$X$2:$X$884,Trades!$E$2:$E$884,$A4) -> 151.09 | G4: =SUMIFS(Trades!$X$2:$X$884,Trades!$E$2:$E$884,$A4,Trades!$X$2:$X$884,">0") -> 294.03 | H4: =SUMIFS(Trades!$X$2:$X$884,Trades!$E$2:$E$884,$A4,Trades!$X$2:$X$884,"<0") -> -142.94 | I4: =IFERROR(G4/-H4,"no loss") -> 2.0570169 | J4: =_xlfn.MAXIFS(Trades!$X$2:$X$884,Trades!$E$2:$E$884,$A4) -> 170.07 | K4: =_xlfn.MINIFS(Trades!$X$2:$X$884,Trades!$E$2:$E$884,$A4) -> -71.54 | L4: =SUMIFS(Trades!$Y$2:$Y$884,Trades!$E$2:$E$884,$A4) -> 2.0501535 | M4: =P3 -> 99604.47 | N4: =IFERROR(F4/M4,0) -> 0.0015168998 | O4: =IF(F4<0,"down week","") | P4: =M4+F4 -> 99755.56 | Q4: =P4-Summary!$C$5 -> -244.44
A5: 45040 | B5: =COUNTIFS(Trades!$E$2:$E$884,$A5) -> 4 | C5: =COUNTIFS(Trades!$E$2:$E$884,$A5,Trades!$Z$2:$Z$884,"Win") -> 0 | D5: =COUNTIFS(Trades!$E$2:$E$884,$A5,Trades!$Z$2:$Z$884,"Loss") -> 4 | E5: =IFERROR(C5/B5,0) -> 0 | F5: =SUMIFS(Trades!$X$2:$X$884,Trades!$E$2:$E$884,$A5) -> -393.78 | G5: =SUMIFS(Trades!$X$2:$X$884,Trades!$E$2:$E$884,$A5,Trades!$X$2:$X$884,">0") -> 0 | H5: =SUMIFS(Trades!$X$2:$X$884,Trades!$E$2:$E$884,$A5,Trades!$X$2:$X$884,"<0") -> -393.78 | I5: =IFERROR(G5/-H5,"no loss") -> 0 | J5: =_xlfn.MAXIFS(Trades!$X$2:$X$884,Trades!$E$2:$E$884,$A5) -> -12.92 | K5: =_xlfn.MINIFS(Trades!$X$2:$X$884,Trades!$E$2:$E$884,$A5) -> -209.98 | L5: =SUMIFS(Trades!$Y$2:$Y$884,Trades!$E$2:$E$884,$A5) -> -3.2375505 | M5: =P4 -> 99755.56 | N5: =IFERROR(F5/M5,0) -> -0.0039474491 | O5: =IF(F5<0,"down week","") -> down week | P5: =M5+F5 -> 99361.78 | Q5: =P5-Summary!$C$5 -> -638.22
A6: 45047 | B6: =COUNTIFS(Trades!$E$2:$E$884,$A6) -> 5 | C6: =COUNTIFS(Trades!$E$2:$E$884,$A6,Trades!$Z$2:$Z$884,"Win") -> 2 | D6: =COUNTIFS(Trades!$E$2:$E$884,$A6,Trades!$Z$2:$Z$884,"Loss") -> 3 | E6: =IFERROR(C6/B6,0) -> 0.4 | F6: =SUMIFS(Trades!$X$2:$X$884,Trades!$E$2:$E$884,$A6) -> 296.44 | G6: =SUMIFS(Trades!$X$2:$X$884,Trades!$E$2:$E$884,$A6,Trades!$X$2:$X$884,">0") -> 545.52 | H6: =SUMIFS(Trades!$X$2:$X$884,Trades!$E$2:$E$884,$A6,Trades!$X$2:$X$884,"<0") -> -249.08 | I6: =IFERROR(G6/-H6,"no loss") -> 2.1901397 | J6: =_xlfn.MAXIFS(Trades!$X$2:$X$884,Trades!$E$2:$E$884,$A6) -> 310.99 | K6: =_xlfn.MINIFS(Trades!$X$2:$X$884,Trades!$E$2:$E$884,$A6) -> -171.35 | L6: =SUMIFS(Trades!$Y$2:$Y$884,Trades!$E$2:$E$884,$A6) -> 1.2329055 | M6: =P5 -> 99361.78 | N6: =IFERROR(F6/M6,0) -> 0.0029834409 | O6: =IF(F6<0,"down week","") | P6: =M6+F6 -> 99658.22 | Q6: =P6-Summary!$C$5 -> -341.78
A7: 45054 | B7: =COUNTIFS(Trades!$E$2:$E$884,$A7) -> 6 | C7: =COUNTIFS(Trades!$E$2:$E$884,$A7,Trades!$Z$2:$Z$884,"Win") -> 2 | D7: =COUNTIFS(Trades!$E$2:$E$884,$A7,Trades!$Z$2:$Z$884,"Loss") -> 4 | E7: =IFERROR(C7/B7,0) -> 0.33333333 | F7: =SUMIFS(Trades!$X$2:$X$884,Trades!$E$2:$E$884,$A7) -> 259.25 | G7: =SUMIFS(Trades!$X$2:$X$884,Trades!$E$2:$E$884,$A7,Trades!$X$2:$X$884,">0") -> 484.31 | H7: =SUMIFS(Trades!$X$2:$X$884,Trades!$E$2:$E$884,$A7,Trades!$X$2:$X$884,"<0") -> -225.06 | I7: =IFERROR(G7/-H7,"no loss") -> 2.151915 | J7: =_xlfn.MAXIFS(Trades!$X$2:$X$884,Trades!$E$2:$E$884,$A7) -> 316.67 | K7: =_xlfn.MINIFS(Trades!$X$2:$X$884,Trades!$E$2:$E$884,$A7) -> -68.05 | L7: =SUMIFS(Trades!$Y$2:$Y$884,Trades!$E$2:$E$884,$A7) -> -0.21620756 | M7: =P6 -> 99658.22 | N7: =IFERROR(F7/M7,0) -> 0.002601391 | O7: =IF(F7<0,"down week","") | P7: =M7+F7 -> 99917.47 | Q7: =P7-Summary!$C$5 -> -82.53
A8: 45061 | B8: =COUNTIFS(Trades!$E$2:$E$884,$A8) -> 4 | C8: =COUNTIFS(Trades!$E$2:$E$884,$A8,Trades!$Z$2:$Z$884,"Win") -> 1 | D8: =COUNTIFS(Trades!$E$2:$E$884,$A8,Trades!$Z$2:$Z$884,"Loss") -> 3 | E8: =IFERROR(C8/B8,0) -> 0.25 | F8: =SUMIFS(Trades!$X$2:$X$884,Trades!$E$2:$E$884,$A8) -> -5.4 | G8: =SUMIFS(Trades!$X$2:$X$884,Trades!$E$2:$E$884,$A8,Trades!$X$2:$X$884,">0") -> 128.45 | H8: =SUMIFS(Trades!$X$2:$X$884,Trades!$E$2:$E$884,$A8,Trades!$X$2:$X$884,"<0") -> -133.85 | I8: =IFERROR(G8/-H8,"no loss") -> 0.95965633 | J8: =_xlfn.MAXIFS(Trades!$X$2:$X$884,Trades!$E$2:$E$884,$A8) -> 128.45 | K8: =_xlfn.MINIFS(Trades!$X$2:$X$884,Trades!$E$2:$E$884,$A8) -> -70.03 | L8: =SUMIFS(Trades!$Y$2:$Y$884,Trades!$E$2:$E$884,$A8) -> 0.66966437 | M8: =P7 -> 99917.47 | N8: =IFERROR(F8/M8,0) -> -5.4044603e-05 | O8: =IF(F8<0,"down week","") -> down week | P8: =M8+F8 -> 99912.07 | Q8: =P8-Summary!$C$5 -> -87.93
A9: 45068 | B9: =COUNTIFS(Trades!$E$2:$E$884,$A9) -> 6 | C9: =COUNTIFS(Trades!$E$2:$E$884,$A9,Trades!$Z$2:$Z$884,"Win") -> 0 | D9: =COUNTIFS(Trades!$E$2:$E$884,$A9,Trades!$Z$2:$Z$884,"Loss") -> 6 | E9: =IFERROR(C9/B9,0) -> 0 | F9: =SUMIFS(Trades!$X$2:$X$884,Trades!$E$2:$E$884,$A9) -> -543.22 | G9: =SUMIFS(Trades!$X$2:$X$884,Trades!$E$2:$E$884,$A9,Trades!$X$2:$X$884,">0") -> 0 | H9: =SUMIFS(Trades!$X$2:$X$884,Trades!$E$2:$E$884,$A9,Trades!$X$2:$X$884,"<0") -> -543.22 | I9: =IFERROR(G9/-H9,"no loss") -> 0 | J9: =_xlfn.MAXIFS(Trades!$X$2:$X$884,Trades!$E$2:$E$884,$A9) -> -2.05 | K9: =_xlfn.MINIFS(Trades!$X$2:$X$884,Trades!$E$2:$E$884,$A9) -> -365.06 | L9: =SUMIFS(Trades!$Y$2:$Y$884,Trades!$E$2:$E$884,$A9) -> -4.1468431 | M9: =P8 -> 99912.07 | N9: =IFERROR(F9/M9,0) -> -0.0054369807 | O9: =IF(F9<0,"down week","") -> down week | P9: =M9+F9 -> 99368.85 | Q9: =P9-Summary!$C$5 -> -631.15
A10: 45075 | B10: =COUNTIFS(Trades!$E$2:$E$884,$A10) -> 7 | C10: =COUNTIFS(Trades!$E$2:$E$884,$A10,Trades!$Z$2:$Z$884,"Win") -> 3 | D10: =COUNTIFS(Trades!$E$2:$E$884,$A10,Trades!$Z$2:$Z$884,"Loss") -> 4 | E10: =IFERROR(C10/B10,0) -> 0.42857143 | F10: =SUMIFS(Trades!$X$2:$X$884,Trades!$E$2:$E$884,$A10) -> 90.26 | G10: =SUMIFS(Trades!$X$2:$X$884,Trades!$E$2:$E$884,$A10,Trades!$X$2:$X$884,">0") -> 401.5 | H10: =SUMIFS(Trades!$X$2:$X$884,Trades!$E$2:$E$884,$A10,Trades!$X$2:$X$884,"<0") -> -311.24 | I10: =IFERROR(G10/-H10,"no loss") -> 1.2900013 | J10: =_xlfn.MAXIFS(Trades!$X$2:$X$884,Trades!$E$2:$E$884,$A10) -> 157.36 | K10: =_xlfn.MINIFS(Trades!$X$2:$X$884,Trades!$E$2:$E$884,$A10) -> -133.3 | L10: =SUMIFS(Trades!$Y$2:$Y$884,Trades!$E$2:$E$884,$A10) -> 3.9163363 | M10: =P9 -> 99368.85 | N10: =IFERROR(F10/M10,0) -> 0.00090833294 | O10: =IF(F10<0,"down week","") | P10: =M10+F10 -> 99459.11 | Q10: =P10-Summary!$C$5 -> -540.89
A11: 45082 | B11: =COUNTIFS(Trades!$E$2:$E$884,$A11) -> 5 | C11: =COUNTIFS(Trades!$E$2:$E$884,$A11,Trades!$Z$2:$Z$884,"Win") -> 2 | D11: =COUNTIFS(Trades!$E$2:$E$884,$A11,Trades!$Z$2:$Z$884,"Loss") -> 3 | E11: =IFERROR(C11/B11,0) -> 0.4 | F11: =SUMIFS(Trades!$X$2:$X$884,Trades!$E$2:$E$884,$A11) -> 216.76 | G11: =SUMIFS(Trades!$X$2:$X$884,Trades!$E$2:$E$884,$A11,Trades!$X$2:$X$884,">0") -> 266.14 | H11: =SUMIFS(Trades!$X$2:$X$884,Trades!$E$2:$E$884,$A11,Trades!$X$2:$X$884,"<0") -> -49.38 | I11: =IFERROR(G11/-H11,"no loss") -> 5.3896314 | J11: =_xlfn.MAXIFS(Trades!$X$2:$X$884,Trades!$E$2:$E$884,$A11) -> 175.62 | K11: =_xlfn.MINIFS(Trades!$X$2:$X$884,Trades!$E$2:$E$884,$A11) -> -48 | L11: =SUMIFS(Trades!$Y$2:$Y$884,Trades!$E$2:$E$884,$A11) -> 3.5580984 | M11: =P10 -> 99459.11 | N11: =IFERROR(F11/M11,0) -> 0.0021793881 | O11: =IF(F11<0,"down week","") | P11: =M11+F11 -> 99675.87 | Q11: =P11-Summary!$C$5 -> -324.13
A12: 45089 | B12: =COUNTIFS(Trades!$E$2:$E$884,$A12) -> 5 | C12: =COUNTIFS(Trades!$E$2:$E$884,$A12,Trades!$Z$2:$Z$884,"Win") -> 1 | D12: =COUNTIFS(Trades!$E$2:$E$884,$A12,Trades!$Z$2:$Z$884,"Loss") -> 4 | E12: =IFERROR(C12/B12,0) -> 0.2 | F12: =SUMIFS(Trades!$X$2:$X$884,Trades!$E$2:$E$884,$A12) -> -68.47 | G12: =SUMIFS(Trades!$X$2:$X$884,Trades!$E$2:$E$884,$A12,Trades!$X$2:$X$884,">0") -> 110.82 | H12: =SUMIFS(Trades!$X$2:$X$884,Trades!$E$2:$E$884,$A12,Trades!$X$2:$X$884,"<0") -> -179.29 | I12: =IFERROR(G12/-H12,"no loss") -> 0.61810475 | J12: =_xlfn.MAXIFS(Trades!$X$2:$X$884,Trades!$E$2:$E$884,$A12) -> 110.82 | K12: =_xlfn.MINIFS(Trades!$X$2:$X$884,Trades!$E$2:$E$884,$A12) -> -110.94 | L12: =SUMIFS(Trades!$Y$2:$Y$884,Trades!$E$2:$E$884,$A12) -> -0.055908415 | M12: =P11 -> 99675.87 | N12: =IFERROR(F12/M12,0) -> -0.00068692653 | O12: =IF(F12<0,"down week","") -> down week | P12: =M12+F12 -> 99607.4 | Q12: =P12-Summary!$C$5 -> -392.6
A13: 45096 | B13: =COUNTIFS(Trades!$E$2:$E$884,$A13) -> 5 | C13: =COUNTIFS(Trades!$E$2:$E$884,$A13,Trades!$Z$2:$Z$884,"Win") -> 1 | D13: =COUNTIFS(Trades!$E$2:$E$884,$A13,Trades!$Z$2:$Z$884,"Loss") -> 4 | E13: =IFERROR(C13/B13,0) -> 0.2 | F13: =SUMIFS(Trades!$X$2:$X$884,Trades!$E$2:$E$884,$A13) -> 111.7 | G13: =SUMIFS(Trades!$X$2:$X$884,Trades!$E$2:$E$884,$A13,Trades!$X$2:$X$884,">0") -> 255.61 | H13: =SUMIFS(Trades!$X$2:$X$884,Trades!$E$2:$E$884,$A13,Trades!$X$2:$X$884,"<0") -> -143.91 | I13: =IFERROR(G13/-H13,"no loss") -> 1.7761796 | J13: =_xlfn.MAXIFS(Trades!$X$2:$X$884,Trades!$E$2:$E$884,$A13) -> 255.61 | K13: =_xlfn.MINIFS(Trades!$X$2:$X$884,Trades!$E$2:$E$884,$A13) -> -56.55 | L13: =SUMIFS(Trades!$Y$2:$Y$884,Trades!$E$2:$E$884,$A13) -> -1.1203487 | M13: =P12 -> 99607.4 | N13: =IFERROR(F13/M13,0) -> 0.0011214026 | O13: =IF(F13<0,"down week","") | P13: =M13+F13 -> 99719.1 | Q13: =P13-Summary!$C$5 -> -280.9
A14: 45103 | B14: =COUNTIFS(Trades!$E$2:$E$884,$A14) -> 3 | C14: =COUNTIFS(Trades!$E$2:$E$884,$A14,Trades!$Z$2:$Z$884,"Win") -> 3 | D14: =COUNTIFS(Trades!$E$2:$E$884,$A14,Trades!$Z$2:$Z$884,"Loss") -> 0 | E14: =IFERROR(C14/B14,0) -> 1 | F14: =SUMIFS(Trades!$X$2:$X$884,Trades!$E$2:$E$884,$A14) -> 795.18 | G14: =SUMIFS(Trades!$X$2:$X$884,Trades!$E$2:$E$884,$A14,Trades!$X$2:$X$884,">0") -> 795.18 | H14: =SUMIFS(Trades!$X$2:$X$884,Trades!$E$2:$E$884,$A14,Trades!$X$2:$X$884,"<0") -> 0 | I14: =IFERROR(G14/-H14,"no loss") -> no loss | J14: =_xlfn.MAXIFS(Trades!$X$2:$X$884,Trades!$E$2:$E$884,$A14) -> 313.44 | K14: =_xlfn.MINIFS(Trades!$X$2:$X$884,Trades!$E$2:$E$884,$A14) -> 180.3 | L14: =SUMIFS(Trades!$Y$2:$Y$884,Trades!$E$2:$E$884,$A14) -> 6.0266209 | M14: =P13 -> 99719.1 | N14: =IFERROR(F14/M14,0) -> 0.0079741995 | O14: =IF(F14<0,"down week","") | P14: =M14+F14 -> 100514.28 | Q14: =P14-Summary!$C$5 -> 514.28
... A183: 46286 | B183: =COUNTIFS(Trades!$E$2:$E$884,$A183) -> 6 | C183: =COUNTIFS(Trades!$E$2:$E$884,$A183,Trades!$Z$2:$Z$884,"Win") -> 3 | D183: =COUNTIFS(Trades!$E$2:$E$884,$A183,Trades!$Z$2:$Z$884,"Loss") -> 3 | E183: =IFERROR(C183/B183,0) -> 0.5 | F183: =SUMIFS(Trades!$X$2:$X$884,Trades!$E$2:$E$884,$A183) -> 70.85 | G183: =SUMIFS(Trades!$X$2:$X$884,Trades!$E$2:$E$884,$A183,Trades!$X$2:$X$884,">0") -> 293.45 | H183: =SUMIFS(Trades!$X$2:$X$884,Trades!$E$2:$E$884,$A183,Trades!$X$2:$X$884,"<0") -> -222.6 | I183: =IFERROR(G183/-H183,"no loss") -> 1.3182839 | J183: =_xlfn.MAXIFS(Trades!$X$2:$X$884,Trades!$E$2:$E$884,$A183) -> 111.11 | K183: =_xlfn.MINIFS(Trades!$X$2:$X$884,Trades!$E$2:$E$884,$A183) -> -180.88 | L183: =SUMIFS(Trades!$Y$2:$Y$884,Trades!$E$2:$E$884,$A183) -> 4.2587431 | M183: =P182 -> 117646.84 | N183: =IFERROR(F183/M183,0) -> 0.00060222612 | O183: =IF(F183<0,"down week","") | P183: =M183+F183 -> 117717.69 | Q183: =P183-Summary!$C$5 -> 17717.69
A185: TOTAL | B185: =SUM(B2:B183) -> 883 | C185: =SUM(C2:C183) -> 282 | D185: =SUM(D2:D183) -> 593 | E185: =IFERROR(C185/B185,0) -> 0.3193658 | F185: =SUM(F2:F183) -> 17717.69 | G185: =SUM(G2:G183) -> 64334.51 | H185: =SUM(H2:H183) -> -46616.82 | I185: =IFERROR(G185/-H185,0) -> 1.3800708 | L185: =SUM(L2:L183) -> 176.66944 | N185: =IFERROR(F185/M2,0) -> 0.1771769 | O185: =COUNTIF(F2:F183,">0")&" up / "&COUNTIF(F2:F183,"<0")&" down" -> 102 up / 80 down

Sheet Daily
A1: Date | B1: Trades | C1: Wins | D1: Losses | E1: Win rate | F1: Net profit | G1: Gross profit | H1: Gross loss | I1: Profit factor | J1: Best trade | K1: Worst trade | L1: Total R | M1: Start balance | N1: Return % | O1: Limit check | P1: End balance | Q1: Cumulative net | R1: Weekday
A2: 45020 | B2: =COUNTIFS(Trades!$D$2:$D$884,$A2) -> 1 | C2: =COUNTIFS(Trades!$D$2:$D$884,$A2,Trades!$Z$2:$Z$884,"Win") -> 1 | D2: =COUNTIFS(Trades!$D$2:$D$884,$A2,Trades!$Z$2:$Z$884,"Loss") -> 0 | E2: =IFERROR(C2/B2,0) -> 1 | F2: =SUMIFS(Trades!$X$2:$X$884,Trades!$D$2:$D$884,$A2) -> 85.68 | G2: =SUMIFS(Trades!$X$2:$X$884,Trades!$D$2:$D$884,$A2,Trades!$X$2:$X$884,">0") -> 85.68 | H2: =SUMIFS(Trades!$X$2:$X$884,Trades!$D$2:$D$884,$A2,Trades!$X$2:$X$884,"<0") -> 0 | I2: =IFERROR(G2/-H2,"no loss") -> no loss | J2: =_xlfn.MAXIFS(Trades!$X$2:$X$884,Trades!$D$2:$D$884,$A2) -> 85.68 | K2: =_xlfn.MINIFS(Trades!$X$2:$X$884,Trades!$D$2:$D$884,$A2) -> 85.68 | L2: =SUMIFS(Trades!$Y$2:$Y$884,Trades!$D$2:$D$884,$A2) -> 2.038835 | M2: =Summary!$C$5 -> 100000 | N2: =IFERROR(F2/M2,0) -> 0.0008568 | O2: =IF(-N2>=Summary!$C$7,"BREACH","") | P2: =M2+F2 -> 100085.68 | Q2: =P2-Summary!$C$5 -> 85.68 | R2: =TEXT(A2,"ddd") -> Tue
A3: 45021 | B3: =COUNTIFS(Trades!$D$2:$D$884,$A3) -> 1 | C3: =COUNTIFS(Trades!$D$2:$D$884,$A3,Trades!$Z$2:$Z$884,"Win") -> 0 | D3: =COUNTIFS(Trades!$D$2:$D$884,$A3,Trades!$Z$2:$Z$884,"Loss") -> 1 | E3: =IFERROR(C3/B3,0) -> 0 | F3: =SUMIFS(Trades!$X$2:$X$884,Trades!$D$2:$D$884,$A3) -> -1.9 | G3: =SUMIFS(Trades!$X$2:$X$884,Trades!$D$2:$D$884,$A3,Trades!$X$2:$X$884,">0") -> 0 | H3: =SUMIFS(Trades!$X$2:$X$884,Trades!$D$2:$D$884,$A3,Trades!$X$2:$X$884,"<0") -> -1.9 | I3: =IFERROR(G3/-H3,"no loss") -> 0 | J3: =_xlfn.MAXIFS(Trades!$X$2:$X$884,Trades!$D$2:$D$884,$A3) -> -1.9 | K3: =_xlfn.MINIFS(Trades!$X$2:$X$884,Trades!$D$2:$D$884,$A3) -> -1.9 | L3: =SUMIFS(Trades!$Y$2:$Y$884,Trades!$D$2:$D$884,$A3) -> -0.013942703 | M3: =P2 -> 100085.68 | N3: =IFERROR(F3/M3,0) -> -1.8983735e-05 | O3: =IF(-N3>=Summary!$C$7,"BREACH","") | P3: =M3+F3 -> 100083.78 | Q3: =P3-Summary!$C$5 -> 83.78 | R3: =TEXT(A3,"ddd") -> Wed
A4: 45022 | B4: =COUNTIFS(Trades!$D$2:$D$884,$A4) -> 1 | C4: =COUNTIFS(Trades!$D$2:$D$884,$A4,Trades!$Z$2:$Z$884,"Win") -> 1 | D4: =COUNTIFS(Trades!$D$2:$D$884,$A4,Trades!$Z$2:$Z$884,"Loss") -> 0 | E4: =IFERROR(C4/B4,0) -> 1 | F4: =SUMIFS(Trades!$X$2:$X$884,Trades!$D$2:$D$884,$A4) -> 140.56 | G4: =SUMIFS(Trades!$X$2:$X$884,Trades!$D$2:$D$884,$A4,Trades!$X$2:$X$884,">0") -> 140.56 | H4: =SUMIFS(Trades!$X$2:$X$884,Trades!$D$2:$D$884,$A4,Trades!$X$2:$X$884,"<0") -> 0 | I4: =IFERROR(G4/-H4,"no loss") -> no loss | J4: =_xlfn.MAXIFS(Trades!$X$2:$X$884,Trades!$D$2:$D$884,$A4) -> 140.56 | K4: =_xlfn.MINIFS(Trades!$X$2:$X$884,Trades!$D$2:$D$884,$A4) -> 140.56 | L4: =SUMIFS(Trades!$Y$2:$Y$884,Trades!$D$2:$D$884,$A4) -> 2.0365112 | M4: =P3 -> 100083.78 | N4: =IFERROR(F4/M4,0) -> 0.0014044234 | O4: =IF(-N4>=Summary!$C$7,"BREACH","") | P4: =M4+F4 -> 100224.34 | Q4: =P4-Summary!$C$5 -> 224.34 | R4: =TEXT(A4,"ddd") -> Thu
A5: 45026 | B5: =COUNTIFS(Trades!$D$2:$D$884,$A5) -> 2 | C5: =COUNTIFS(Trades!$D$2:$D$884,$A5,Trades!$Z$2:$Z$884,"Win") -> 1 | D5: =COUNTIFS(Trades!$D$2:$D$884,$A5,Trades!$Z$2:$Z$884,"Loss") -> 1 | E5: =IFERROR(C5/B5,0) -> 0.5 | F5: =SUMIFS(Trades!$X$2:$X$884,Trades!$D$2:$D$884,$A5) -> -8.57 | G5: =SUMIFS(Trades!$X$2:$X$884,Trades!$D$2:$D$884,$A5,Trades!$X$2:$X$884,">0") -> 60.72 | H5: =SUMIFS(Trades!$X$2:$X$884,Trades!$D$2:$D$884,$A5,Trades!$X$2:$X$884,"<0") -> -69.29 | I5: =IFERROR(G5/-H5,"no loss") -> 0.87631693 | J5: =_xlfn.MAXIFS(Trades!$X$2:$X$884,Trades!$D$2:$D$884,$A5) -> 60.72 | K5: =_xlfn.MINIFS(Trades!$X$2:$X$884,Trades!$D$2:$D$884,$A5) -> -69.29 | L5: =SUMIFS(Trades!$Y$2:$Y$884,Trades!$D$2:$D$884,$A5) -> 1.0441183 | M5: =P4 -> 100224.34 | N5: =IFERROR(F5/M5,0) -> -8.5508171e-05 | O5: =IF(-N5>=Summary!$C$7,"BREACH","") | P5: =M5+F5 -> 100215.77 | Q5: =P5-Summary!$C$5 -> 215.77 | R5: =TEXT(A5,"ddd") -> Mon
A6: 45027 | B6: =COUNTIFS(Trades!$D$2:$D$884,$A6) -> 1 | C6: =COUNTIFS(Trades!$D$2:$D$884,$A6,Trades!$Z$2:$Z$884,"Win") -> 0 | D6: =COUNTIFS(Trades!$D$2:$D$884,$A6,Trades!$Z$2:$Z$884,"Loss") -> 1 | E6: =IFERROR(C6/B6,0) -> 0 | F6: =SUMIFS(Trades!$X$2:$X$884,Trades!$D$2:$D$884,$A6) -> -35.36 | G6: =SUMIFS(Trades!$X$2:$X$884,Trades!$D$2:$D$884,$A6,Trades!$X$2:$X$884,">0") -> 0 | H6: =SUMIFS(Trades!$X$2:$X$884,Trades!$D$2:$D$884,$A6,Trades!$X$2:$X$884,"<0") -> -35.36 | I6: =IFERROR(G6/-H6,"no loss") -> 0 | J6: =_xlfn.MAXIFS(Trades!$X$2:$X$884,Trades!$D$2:$D$884,$A6) -> -35.36 | K6: =_xlfn.MINIFS(Trades!$X$2:$X$884,Trades!$D$2:$D$884,$A6) -> -35.36 | L6: =SUMIFS(Trades!$Y$2:$Y$884,Trades!$D$2:$D$884,$A6) -> -1.0116732 | M6: =P5 -> 100215.77 | N6: =IFERROR(F6/M6,0) -> -0.00035283868 | O6: =IF(-N6>=Summary!$C$7,"BREACH","") | P6: =M6+F6 -> 100180.41 | Q6: =P6-Summary!$C$5 -> 180.41 | R6: =TEXT(A6,"ddd") -> Tue
A7: 45028 | B7: =COUNTIFS(Trades!$D$2:$D$884,$A7) -> 2 | C7: =COUNTIFS(Trades!$D$2:$D$884,$A7,Trades!$Z$2:$Z$884,"Win") -> 0 | D7: =COUNTIFS(Trades!$D$2:$D$884,$A7,Trades!$Z$2:$Z$884,"Loss") -> 2 | E7: =IFERROR(C7/B7,0) -> 0 | F7: =SUMIFS(Trades!$X$2:$X$884,Trades!$D$2:$D$884,$A7) -> -401.81 | G7: =SUMIFS(Trades!$X$2:$X$884,Trades!$D$2:$D$884,$A7,Trades!$X$2:$X$884,">0") -> 0 | H7: =SUMIFS(Trades!$X$2:$X$884,Trades!$D$2:$D$884,$A7,Trades!$X$2:$X$884,"<0") -> -401.81 | I7: =IFERROR(G7/-H7,"no loss") -> 0 | J7: =_xlfn.MAXIFS(Trades!$X$2:$X$884,Trades!$D$2:$D$884,$A7) -> -47.33 | K7: =_xlfn.MINIFS(Trades!$X$2:$X$884,Trades!$D$2:$D$884,$A7) -> -354.48 | L7: =SUMIFS(Trades!$Y$2:$Y$884,Trades!$D$2:$D$884,$A7) -> -2.0316835 | M7: =P6 -> 100180.41 | N7: =IFERROR(F7/M7,0) -> -0.004010864 | O7: =IF(-N7>=Summary!$C$7,"BREACH","") | P7: =M7+F7 -> 99778.6 | Q7: =P7-Summary!$C$5 -> -221.4 | R7: =TEXT(A7,"ddd") -> Wed
A8: 45029 | B8: =COUNTIFS(Trades!$D$2:$D$884,$A8) -> 1 | C8: =COUNTIFS(Trades!$D$2:$D$884,$A8,Trades!$Z$2:$Z$884,"Win") -> 0 | D8: =COUNTIFS(Trades!$D$2:$D$884,$A8,Trades!$Z$2:$Z$884,"Loss") -> 1 | E8: =IFERROR(C8/B8,0) -> 0 | F8: =SUMIFS(Trades!$X$2:$X$884,Trades!$D$2:$D$884,$A8) -> -34.93 | G8: =SUMIFS(Trades!$X$2:$X$884,Trades!$D$2:$D$884,$A8,Trades!$X$2:$X$884,">0") -> 0 | H8: =SUMIFS(Trades!$X$2:$X$884,Trades!$D$2:$D$884,$A8,Trades!$X$2:$X$884,"<0") -> -34.93 | I8: =IFERROR(G8/-H8,"no loss") -> 0 | J8: =_xlfn.MAXIFS(Trades!$X$2:$X$884,Trades!$D$2:$D$884,$A8) -> -34.93 | K8: =_xlfn.MINIFS(Trades!$X$2:$X$884,Trades!$D$2:$D$884,$A8) -> -34.93 | L8: =SUMIFS(Trades!$Y$2:$Y$884,Trades!$D$2:$D$884,$A8) -> -1.1064302 | M8: =P7 -> 99778.6 | N8: =IFERROR(F8/M8,0) -> -0.00035007507 | O8: =IF(-N8>=Summary!$C$7,"BREACH","") | P8: =M8+F8 -> 99743.67 | Q8: =P8-Summary!$C$5 -> -256.33 | R8: =TEXT(A8,"ddd") -> Thu
A9: 45030 | B9: =COUNTIFS(Trades!$D$2:$D$884,$A9) -> 1 | C9: =COUNTIFS(Trades!$D$2:$D$884,$A9,Trades!$Z$2:$Z$884,"Win") -> 0 | D9: =COUNTIFS(Trades!$D$2:$D$884,$A9,Trades!$Z$2:$Z$884,"Loss") -> 1 | E9: =IFERROR(C9/B9,0) -> 0 | F9: =SUMIFS(Trades!$X$2:$X$884,Trades!$D$2:$D$884,$A9) -> -139.2 | G9: =SUMIFS(Trades!$X$2:$X$884,Trades!$D$2:$D$884,$A9,Trades!$X$2:$X$884,">0") -> 0 | H9: =SUMIFS(Trades!$X$2:$X$884,Trades!$D$2:$D$884,$A9,Trades!$X$2:$X$884,"<0") -> -139.2 | I9: =IFERROR(G9/-H9,"no loss") -> 0 | J9: =_xlfn.MAXIFS(Trades!$X$2:$X$884,Trades!$D$2:$D$884,$A9) -> -139.2 | K9: =_xlfn.MINIFS(Trades!$X$2:$X$884,Trades!$D$2:$D$884,$A9) -> -139.2 | L9: =SUMIFS(Trades!$Y$2:$Y$884,Trades!$D$2:$D$884,$A9) -> -1.0460188 | M9: =P8 -> 99743.67 | N9: =IFERROR(F9/M9,0) -> -0.0013955773 | O9: =IF(-N9>=Summary!$C$7,"BREACH","") | P9: =M9+F9 -> 99604.47 | Q9: =P9-Summary!$C$5 -> -395.53 | R9: =TEXT(A9,"ddd") -> Fri
A10: 45034 | B10: =COUNTIFS(Trades!$D$2:$D$884,$A10) -> 1 | C10: =COUNTIFS(Trades!$D$2:$D$884,$A10,Trades!$Z$2:$Z$884,"Win") -> 0 | D10: =COUNTIFS(Trades!$D$2:$D$884,$A10,Trades!$Z$2:$Z$884,"Loss") -> 1 | E10: =IFERROR(C10/B10,0) -> 0 | F10: =SUMIFS(Trades!$X$2:$X$884,Trades!$D$2:$D$884,$A10) -> -71.54 | G10: =SUMIFS(Trades!$X$2:$X$884,Trades!$D$2:$D$884,$A10,Trades!$X$2:$X$884,">0") -> 0 | H10: =SUMIFS(Trades!$X$2:$X$884,Trades!$D$2:$D$884,$A10,Trades!$X$2:$X$884,"<0") -> -71.54 | I10: =IFERROR(G10/-H10,"no loss") -> 0 | J10: =_xlfn.MAXIFS(Trades!$X$2:$X$884,Trades!$D$2:$D$884,$A10) -> -71.54 | K10: =_xlfn.MINIFS(Trades!$X$2:$X$884,Trades!$D$2:$D$884,$A10) -> -71.54 | L10: =SUMIFS(Trades!$Y$2:$Y$884,Trades!$D$2:$D$884,$A10) -> -1.0145215 | M10: =P9 -> 99604.47 | N10: =IFERROR(F10/M10,0) -> -0.00071824086 | O10: =IF(-N10>=Summary!$C$7,"BREACH","") | P10: =M10+F10 -> 99532.93 | Q10: =P10-Summary!$C$5 -> -467.07 | R10: =TEXT(A10,"ddd") -> Tue
